Workbook

Sheet Data
A1: 5.1 | B1: 3.5 | C1: 1.4 | D1: 0.2 | E1: Iris-setosa
A2: 4.9 | B2: 3 | C2: 1.4 | D2: 0.2 | E2: Iris-setosa
A3: 4.7 | B3: 3.2 | C3: 1.3 | D3: 0.2 | E3: Iris-setosa
A4: 4.6 | B4: 3.1 | C4: 1.5 | D4: 0.2 | E4: Iris-setosa
A5: 5 | B5: 3.6 | C5: 1.4 | D5: 0.2 | E5: Iris-setosa
A6: 5.4 | B6: 3.9 | C6: 1.7 | D6: 0.4 | E6: Iris-setosa
A7: 4.6 | B7: 3.4 | C7: 1.4 | D7: 0.3 | E7: Iris-setosa
A8: 5 | B8: 3.4 | C8: 1.5 | D8: 0.2 | E8: Iris-setosa
A9: 4.4 | B9: 2.9 | C9: 1.4 | D9: 0.2 | E9: Iris-setosa
A10: 4.9 | B10: 3.1 | C10: 1.5 | D10: 0.1 | E10: Iris-setosa
A11: 5.4 | B11: 3.7 | C11: 1.5 | D11: 0.2 | E11: Iris-setosa
A12: 4.8 | B12: 3.4 | C12: 1.6 | D12: 0.2 | E12: Iris-setosa
... A100: 5.7 | B100: 2.8 | C100: 4.1 | D100: 1.3 | E100: Iris-versicolor

Sheet SLP-Training
G2: Setosa = 0 | I2: Learning Rate | K2: 0.1
G3: Versicolor = 1 | I3: Bobot bias | N3: dot product | O3: Sigmoid | P3: Prediksi | Q3: error | R3: Sum Square Error
A4: EPOCH | B4: No | C4: X1 | D4: X2 | E4: X3 | F4: X4 | G4: TARGET | H4: Apakah prediksi sama dengan label aslinya? | I4: bias | J4: teta1 | K4: teta2 | L4: teta 3 | M4: teta4 | N4: z | O4: g(z) | S4: Rata-rata Sum Square Error | T4: dbias | U4: dteta1 | V4: dteta2 | W4: dteta3 | X4: dteta4
A5: epoch1 | B5: 1 | C5: 5.1 | D5: 3.5 | E5: 1.4 | F5: 0.2 | G5: 0 | H5: =IF(G5=P5, 1, 0) -> 0 | I5: 0.5 | J5: 0.5 | K5: 0.5 | L5: 0.5 | M5: 0.5 | N5: =I5+J5*C5+K5*D5+L5*E5+F5*M5 -> 5.6 | O5: =1/(1+EXP(-N5)) -> 0.99631576 | P5: =IF(O5>0.5,1,0) -> 1 | Q5: =O5-G5 -> 0.99631576 | R5: =Q5^2 -> 0.99264509 | T5: =2*(O5-G5)*(1-O5)*O5 -> 0.0073142853 | U5: =2*(O5-G5)*(1-O5)*O5*C5 -> 0.037302855 | V5: =2*(O5-G5)*(1-O5)*O5*D5 -> 0.025599999 | W5: =2*(O5-G5)*(1-O5)*O5*E5 -> 0.010239999 | X5: =2*(O5-G5)*(1-O5)*O5*F5 -> 0.0014628571
B6: 2 | C6: 4.9 | D6: 3 | E6: 1.4 | F6: 0.2 | G6: 0 | H6: =IF(G6=P6, 1, 0) -> 0 | I6: =I5-0.1*T5 -> 0.49926857 | J6: =J5-0.1*U5 -> 0.49626971 | K6: =K5-0.1*V5 -> 0.49744 | L6: =L5-0.1*W5 -> 0.498976 | M6: =M5-0.1*X5 -> 0.49985371 | N6: =I6+J6*C6+K6*D6+L6*E6+F6*M6 -> 5.2218473 | O6: =1/(1+EXP(-N6)) -> 0.99463163 | P6: =IF(O6>0.5,1,0) -> 1 | Q6: =O6-G6 -> 0.99463163 | R6: =Q6^2 -> 0.98929207 | T6: =2*(O6-G6)*(1-O6)*O6 -> 0.01062178 | U6: =2*(O6-G6)*(1-O6)*O6*C6 -> 0.052046723 | V6: =2*(O6-G6)*(1-O6)*O6*D6 -> 0.031865341 | W6: =2*(O6-G6)*(1-O6)*O6*E6 -> 0.014870492 | X6: =2*(O6-G6)*(1-O6)*O6*F6 -> 0.0021243561
B7: 3 | C7: 4.7 | D7: 3.2 | E7: 1.3 | F7: 0.2 | G7: 0 | H7: =IF(G7=P7, 1, 0) -> 0 | I7: =I6-0.1*T6 -> 0.49820639 | J7: =J6-0.1*U6 -> 0.49106504 | K7: =K6-0.1*V6 -> 0.49425347 | L7: =L6-0.1*W6 -> 0.49748895 | M7: =M6-0.1*X6 -> 0.49964128 | N7: =I7+J7*C7+K7*D7+L7*E7+F7*M7 -> 5.1344871 | O7: =1/(1+EXP(-N7)) -> 0.99414442 | P7: =IF(O7>0.5,1,0) -> 1 | Q7: =O7-G7 -> 0.99414442 | R7: =Q7^2 -> 0.98832312 | T7: =2*(O7-G7)*(1-O7)*O7 -> 0.011574414 | U7: =2*(O7-G7)*(1-O7)*O7*C7 -> 0.054399748 | V7: =2*(O7-G7)*(1-O7)*O7*D7 -> 0.037038126 | W7: =2*(O7-G7)*(1-O7)*O7*E7 -> 0.015046739 | X7: =2*(O7-G7)*(1-O7)*O7*F7 -> 0.0023148829
B8: 4 | C8: 4.6 | D8: 3.1 | E8: 1.5 | F8: 0.2 | G8: 0 | H8: =IF(G8=P8, 1, 0) -> 0 | I8: =I7-0.1*T7 -> 0.49704895 | J8: =J7-0.1*U7 -> 0.48562507 | K8: =K7-0.1*V7 -> 0.49054965 | L8: =L7-0.1*W7 -> 0.49598428 | M8: =M7-0.1*X7 -> 0.49940979 | N8: =I8+J8*C8+K8*D8+L8*E8+F8*M8 -> 5.0954866 | O8: =1/(1+EXP(-N8)) -> 0.99391295 | P8: =IF(O8>0.5,1,0) -> 1 | Q8: =O8-G8 -> 0.99391295 | R8: =Q8^2 -> 0.98786296 | T8: =2*(O8-G8)*(1-O8)*O8 -> 0.012026336 | U8: =2*(O8-G8)*(1-O8)*O8*C8 -> 0.055321148 | V8: =2*(O8-G8)*(1-O8)*O8*D8 -> 0.037281643 | W8: =2*(O8-G8)*(1-O8)*O8*E8 -> 0.018039505 | X8: =2*(O8-G8)*(1-O8)*O8*F8 -> 0.0024052673
B9: 5 | C9: 5 | D9: 3.6 | E9: 1.4 | F9: 0.2 | G9: 0 | H9: =IF(G9=P9, 1, 0) -> 0 | I9: =I8-0.1*T8 -> 0.49584632 | J9: =J8-0.1*U8 -> 0.48009295 | K9: =K8-0.1*V8 -> 0.48682149 | L9: =L8-0.1*W8 -> 0.49418033 | M9: =M8-0.1*X8 -> 0.49916926 | N9: =I9+J9*C9+K9*D9+L9*E9+F9*M9 -> 5.4405548 | O9: =1/(1+EXP(-N9)) -> 0.99568165 | P9: =IF(O9>0.5,1,0) -> 1 | Q9: =O9-G9 -> 0.99568165 | R9: =Q9^2 -> 0.99138195 | T9: =2*(O9-G9)*(1-O9)*O9 -> 0.0085622637 | U9: =2*(O9-G9)*(1-O9)*O9*C9 -> 0.042811319 | V9: =2*(O9-G9)*(1-O9)*O9*D9 -> 0.030824149 | W9: =2*(O9-G9)*(1-O9)*O9*E9 -> 0.011987169 | X9: =2*(O9-G9)*(1-O9)*O9*F9 -> 0.0017124527
B10: 6 | C10: 5.4 | D10: 3.9 | E10: 1.7 | F10: 0.4 | G10: 0 | H10: =IF(G10=P10, 1, 0) -> 0 | I10: =I9-0.1*T9 -> 0.49499009 | J10: =J9-0.1*U9 -> 0.47581182 | K10: =K9-0.1*V9 -> 0.48373907 | L10: =L9-0.1*W9 -> 0.49298161 | M10: =M9-0.1*X9 -> 0.49899802 | N10: =I10+J10*C10+K10*D10+L10*E10+F10*M10 -> 5.9886243 | O10: =1/(1+EXP(-N10)) -> 0.99749916 | P10: =IF(O10>0.5,1,0) -> 1 | Q10: =O10-G10 -> 0.99749916 | R10: =Q10^2 -> 0.99500457 | T10: =2*(O10-G10)*(1-O10)*O10 -> 0.0049766963 | U10: =2*(O10-G10)*(1-O10)*O10*C10 -> 0.02687416 | V10: =2*(O10-G10)*(1-O10)*O10*D10 -> 0.019409116 | W10: =2*(O10-G10)*(1-O10)*O10*E10 -> 0.0084603838 | X10: =2*(O10-G10)*(1-O10)*O10*F10 -> 0.0019906785
B11: 7 | C11: 4.6 | D11: 3.4 | E11: 1.4 | F11: 0.3 | G11: 0 | H11: =IF(G11=P11, 1, 0) -> 0 | I11: =I10-0.1*T10 -> 0.49449242 | J11: =J10-0.1*U10 -> 0.4731244 | K11: =K10-0.1*V10 -> 0.48179816 | L11: =L10-0.1*W10 -> 0.49213557 | M11: =M10-0.1*X10 -> 0.49879895 | N11: =I11+J11*C11+K11*D11+L11*E11+F11*M11 -> 5.1476079 | O11: =1/(1+EXP(-N11)) -> 0.99422031 | P11: =IF(O11>0.5,1,0) -> 1 | Q11: =O11-G11 -> 0.99422031 | R11: =Q11^2 -> 0.98847402 | T11: =2*(O11-G11)*(1-O11)*O11 -> 0.011426156 | U11: =2*(O11-G11)*(1-O11)*O11*C11 -> 0.05256032 | V11: =2*(O11-G11)*(1-O11)*O11*D11 -> 0.038848932 | W11: =2*(O11-G11)*(1-O11)*O11*E11 -> 0.015996619 | X11: =2*(O11-G11)*(1-O11)*O11*F11 -> 0.0034278469
B12: 8 | C12: 5 | D12: 3.4 | E12: 1.5 | F12: 0.2 | G12: 0 | H12: =IF(G12=P12, 1, 0) -> 0 | I12: =I11-0.1*T11 -> 0.49334981 | J12: =J11-0.1*U11 -> 0.46786837 | K12: =K11-0.1*V11 -> 0.47791327 | L12: =L11-0.1*W11 -> 0.49053591 | M12: =M11-0.1*X11 -> 0.49845617 | N12: =I12+J12*C12+K12*D12+L12*E12+F12*M12 -> 5.2930919 | O12: =1/(1+EXP(-N12)) -> 0.99499894 | P12: =IF(O12>0.5,1,0) -> 1 | Q12: =O12-G12 -> 0.99499894 | R12: =Q12^2 -> 0.99002289 | T12: =2*(O12-G12)*(1-O12)*O12 -> 0.0099023268 | U12: =2*(O12-G12)*(1-O12)*O12*C12 -> 0.049511634 | V12: =2*(O12-G12)*(1-O12)*O12*D12 -> 0.033667911 | W12: =2*(O12-G12)*(1-O12)*O12*E12 -> 0.01485349 | X12: =2*(O12-G12)*(1-O12)*O12*F12 -> 0.0019804654
B13: 9 | C13: 4.4 | D13: 2.9 | E13: 1.4 | F13: 0.2 | G13: 0 | H13: =IF(G13=P13, 1, 0) -> 0 | I13: =I12-0.1*T12 -> 0.49235957 | J13: =J12-0.1*U12 -> 0.46291721 | K13: =K12-0.1*V12 -> 0.47454648 | L13: =L12-0.1*W12 -> 0.48905056 | M13: =M12-0.1*X12 -> 0.49825812 | N13: =I13+J13*C13+K13*D13+L13*E13+F13*M13 -> 4.6897025 | O13: =1/(1+EXP(-N13)) -> 0.99089426 | P13: =IF(O13>0.5,1,0) -> 1 | Q13: =O13-G13 -> 0.99089426 | R13: =Q13^2 -> 0.98187143 | T13: =2*(O13-G13)*(1-O13)*O13 -> 0.017881338 | U13: =2*(O13-G13)*(1-O13)*O13*C13 -> 0.078677888 | V13: =2*(O13-G13)*(1-O13)*O13*D13 -> 0.051855881 | W13: =2*(O13-G13)*(1-O13)*O13*E13 -> 0.025033873 | X13: =2*(O13-G13)*(1-O13)*O13*F13 -> 0.0035762676
B14: 10 | C14: 4.9 | D14: 3.1 | E14: 1.5 | F14: 0.1 | G14: 0 | H14: =IF(G14=P14, 1, 0) -> 0 | I14: =I13-0.1*T13 -> 0.49057144 | J14: =J13-0.1*U13 -> 0.45504942 | K14: =K13-0.1*V13 -> 0.46936089 | L14: =L13-0.1*W13 -> 0.48654717 | M14: =M13-0.1*X13 -> 0.49790049 | N14: =I14+J14*C14+K14*D14+L14*E14+F14*M14 -> 4.9549432 | O14: =1/(1+EXP(-N14)) -> 0.99300085 | P14: =IF(O14>0.5,1,0) -> 1 | Q14: =O14-G14 -> 0.99300085 | R14: =Q14^2 -> 0.98605069 | T14: =2*(O14-G14)*(1-O14)*O14 -> 0.013803028 | U14: =2*(O14-G14)*(1-O14)*O14*C14 -> 0.067634839 | V14: =2*(O14-G14)*(1-O14)*O14*D14 -> 0.042789388 | W14: =2*(O14-G14)*(1-O14)*O14*E14 -> 0.020704543 | X14: =2*(O14-G14)*(1-O14)*O14*F14 -> 0.0013803028
B15: 11 | C15: 5.4 | D15: 3.7 | E15: 1.5 | F15: 0.2 | G15: 0 | H15: =IF(G15=P15, 1, 0) -> 0 | I15: =I14-0.1*T14 -> 0.48919114 | J15: =J14-0.1*U14 -> 0.44828594 | K15: =K14-0.1*V14 -> 0.46508195 | L15: =L14-0.1*W14 -> 0.48447672 | M15: =M14-0.1*X14 -> 0.49776246 | N15: =I15+J15*C15+K15*D15+L15*E15+F15*M15 -> 5.457006 | O15: =1/(1+EXP(-N15)) -> 0.99575181 | P15: =IF(O15>0.5,1,0) -> 1 | Q15: =O15-G15 -> 0.99575181 | R15: =Q15^2 -> 0.99152168 | T15: =2*(O15-G15)*(1-O15)*O15 -> 0.0084243369 | U15: =2*(O15-G15)*(1-O15)*O15*C15 -> 0.045491419 | V15: =2*(O15-G15)*(1-O15)*O15*D15 -> 0.031170047 | W15: =2*(O15-G15)*(1-O15)*O15*E15 -> 0.012636505 | X15: =2*(O15-G15)*(1-O15)*O15*F15 -> 0.0016848674
B16: 12 | C16: 4.8 | D16: 3.4 | E16: 1.6 | F16: 0.2 | G16: 0 | H16: =IF(G16=P16, 1, 0) -> 0 | I16: =I15-0.1*T15 -> 0.4883487 | J16: =J15-0.1*U15 -> 0.44373679 | K16: =K15-0.1*V15 -> 0.46196495 | L16: =L15-0.1*W15 -> 0.48321307 | M16: =M15-0.1*X15 -> 0.49759398 | N16: =I16+J16*C16+K16*D16+L16*E16+F16*M16 -> 5.0616258 | O16: =1/(1+EXP(-N16)) -> 0.99370463 | P16: =IF(O16>0.5,1,0) -> 1 | Q16: =O16-G16 -> 0.99370463 | R16: =Q16^2 -> 0.9874489 | T16: =2*(O16-G16)*(1-O16)*O16 -> 0.012432709 | U16: =2*(O16-G16)*(1-O16)*O16*C16 -> 0.059677003 | V16: =2*(O16-G16)*(1-O16)*O16*D16 -> 0.04227121 | W16: =2*(O16-G16)*(1-O16)*O16*E16 -> 0.019892334 | X16: =2*(O16-G16)*(1-O16)*O16*F16 -> 0.0024865418
B17: 13 | C17: 4.8 | D17: 3 | E17: 1.4 | F17: 0.1 | G17: 0 | H17: =IF(G17=P17, 1, 0) -> 0 | I17: =I16-0.1*T16 -> 0.48710543 | J17: =J16-0.1*U16 -> 0.43776909 | K17: =K16-0.1*V16 -> 0.45773783 | L17: =L16-0.1*W16 -> 0.48122383 | M17: =M16-0.1*X16 -> 0.49734532 | N17: =I17+J17*C17+K17*D17+L17*E17+F17*M17 -> 4.6850585 | O17: =1/(1+EXP(-N17)) -> 0.99085226 | P17: =IF(O17>0.5,1,0) -> 1 | Q17: =O17-G17 -> 0.99085226 | R17: =Q17^2 -> 0.9817882 | T17: =2*(O17-G17)*(1-O17)*O17 -> 0.017962289 | U17: =2*(O17-G17)*(1-O17)*O17*C17 -> 0.086218985 | V17: =2*(O17-G17)*(1-O17)*O17*D17 -> 0.053886866 | W17: =2*(O17-G17)*(1-O17)*O17*E17 -> 0.025147204 | X17: =2*(O17-G17)*(1-O17)*O17*F17 -> 0.0017962289
... B83: 79 | C83: 5.6 | D83: 3 | E83: 4.1 | F83: 1.3 | G83: 1 | H83: =IF(G83=P83, 1, 0) -> 1 | I83: =I82-0.1*T82 -> 0.37983676 | J83: =J82-0.1*U82 -> -0.021902874 | K83: =K82-0.1*V82 -> 0.070081781 | L83: =L82-0.1*W82 -> 0.52242862 | M83: =M82-0.1*X82 -> 0.550491 | N83: =I83+J83*C83+K83*D83+L83*E83+F83*M83 -> 3.3250216 | O83: =1/(1+EXP(-N83)) -> 0.9652773 | P83: =IF(O83>0.5,1,0) -> 1 | Q83: =O83-G83 -> -0.034722704 | R83: =Q83^2 -> 0.0012056662 | T83: =2*(O83-G83)*(1-O83)*O83 -> -0.0023276044 | U83: =2*(O83-G83)*(1-O83)*O83*C83 -> -0.013034585 | V83: =2*(O83-G83)*(1-O83)*O83*D83 -> -0.0069828131 | W83: =2*(O83-G83)*(1-O83)*O83*E83 -> -0.0095431779 | X83: =2*(O83-G83)*(1-O83)*O83*F83 -> -0.0030258857
B84: 80 | C84: 5.5 | D84: 2.5 | E84: 4 | F84: 1.3 | G84: 1 | H84: =IF(G84=P84, 1, 0) -> 1 | I84: =I83-0.1*T83 -> 0.38006952 | J84: =J83-0.1*U83 -> -0.020599416 | K84: =K83-0.1*V83 -> 0.070780062 | L84: =L83-0.1*W83 -> 0.52338294 | M84: =M83-0.1*X83 -> 0.55079359 | N84: =I84+J84*C84+K84*D84+L84*E84+F84*M84 -> 3.2532863 | O84: =1/(1+EXP(-N84)) -> 0.96279102 | P84: =IF(O84>0.5,1,0) -> 1 | Q84: =O84-G84 -> -0.037208978 | R84: =Q84^2 -> 0.0013845081 | S84: =AVERAGE(R5:R84) -> 0.44988866 | T84: =2*(O84-G84)*(1-O84)*O84 -> -0.0026659838 | U84: =2*(O84-G84)*(1-O84)*O84*C84 -> -0.014662911 | V84: =2*(O84-G84)*(1-O84)*O84*D84 -> -0.0066649596 | W84: =2*(O84-G84)*(1-O84)*O84*E84 -> -0.010663935 | X84: =2*(O84-G84)*(1-O84)*O84*F84 -> -0.003465779
A85: epoch2 | B85: 1 | C85: 5.1 | D85: 3.5 | E85: 1.4 | F85: 0.2 | G85: 0 | H85: =IF(G85=P85, 1, 0) -> 0 | I85: =I84-0.1*T84 -> 0.38033612 | J85: =J84-0.1*U84 -> -0.019133125 | K85: =K84-0.1*V84 -> 0.071446558 | L85: =L84-0.1*W84 -> 0.52444933 | M85: =M84-0.1*X84 -> 0.55114017 | N85: =I85+J85*C85+K85*D85+L85*E85+F85*M85 -> 1.3772772 | O85: =1/(1+EXP(-N85)) -> 0.79855336 | P85: =IF(O85>0.5,1,0) -> 1 | Q85: =O85-G85 -> 0.79855336 | R85: =Q85^2 -> 0.63768746 | T85: =2*(O85-G85)*(1-O85)*O85 -> 0.25692 | U85: =2*(O85-G85)*(1-O85)*O85*C85 -> 1.310292 | V85: =2*(O85-G85)*(1-O85)*O85*D85 -> 0.89921999 | W85: =2*(O85-G85)*(1-O85)*O85*E85 -> 0.359688 | X85: =2*(O85-G85)*(1-O85)*O85*F85 -> 0.051384
B86: 2 | C86: 4.9 | D86: 3 | E86: 1.4 | F86: 0.2 | G86: 0 | H86: =IF(G86=P86, 1, 0) -> 0 | I86: =I85-0.1*T85 -> 0.35464412 | J86: =J85-0.1*U85 -> -0.15016232 | K86: =K85-0.1*V85 -> -0.018475441 | L86: =L85-0.1*W85 -> 0.48848053 | M86: =M85-0.1*X85 -> 0.54600177 | N86: =I86+J86*C86+K86*D86+L86*E86+F86*M86 -> 0.3564955 | O86: =1/(1+EXP(-N86)) -> 0.58819183 | P86: =IF(O86>0.5,1,0) -> 1 | Q86: =O86-G86 -> 0.58819183 | R86: =Q86^2 -> 0.34596963 | T86: =2*(O86-G86)*(1-O86)*O86 -> 0.28494624 | U86: =2*(O86-G86)*(1-O86)*O86*C86 -> 1.3962366 | V86: =2*(O86-G86)*(1-O86)*O86*D86 -> 0.85483872 | W86: =2*(O86-G86)*(1-O86)*O86*E86 -> 0.39892474 | X86: =2*(O86-G86)*(1-O86)*O86*F86 -> 0.056989248
B87: 3 | C87: 4.7 | D87: 3.2 | E87: 1.3 | F87: 0.2 | G87: 0 | H87: =IF(G87=P87, 1, 0) -> 1 | I87: =I86-0.1*T86 -> 0.3261495 | J87: =J86-0.1*U86 -> -0.28978598 | K87: =K86-0.1*V86 -> -0.10395931 | L87: =L86-0.1*W86 -> 0.44858806 | M87: =M86-0.1*X86 -> 0.54030284 | N87: =I87+J87*C87+K87*D87+L87*E87+F87*M87 -> -0.67728938 | O87: =1/(1+EXP(-N87)) -> 0.33686655 | P87: =IF(O87>0.5,1,0) -> 0 | Q87: =O87-G87 -> 0.33686655 | R87: =Q87^2 -> 0.11347908 | T87: =2*(O87-G87)*(1-O87)*O87 -> 0.15050354 | U87: =2*(O87-G87)*(1-O87)*O87*C87 -> 0.70736664 | V87: =2*(O87-G87)*(1-O87)*O87*D87 -> 0.48161133 | W87: =2*(O87-G87)*(1-O87)*O87*E87 -> 0.1956546 | X87: =2*(O87-G87)*(1-O87)*O87*F87 -> 0.030100708
B88: 4 | C88: 4.6 | D88: 3.1 | E88: 1.5 | F88: 0.2 | G88: 0 | H88: =IF(G88=P88, 1, 0) -> 1 | I88: =I87-0.1*T87 -> 0.31109914 | J88: =J87-0.1*U87 -> -0.36052265 | K88: =K87-0.1*V87 -> -0.15212045 | L88: =L87-0.1*W87 -> 0.4290226 | M88: =M87-0.1*X87 -> 0.53729277 | N88: =I88+J88*C88+K88*D88+L88*E88+F88*M88 -> -1.067886 | O88: =1/(1+EXP(-N88)) -> 0.25580532 | P88: =IF(O88>0.5,1,0) -> 0 | Q88: =O88-G88 -> 0.25580532 | R88: =Q88^2 -> 0.065436364 | T88: =2*(O88-G88)*(1-O88)*O88 -> 0.097394787 | U88: =2*(O88-G88)*(1-O88)*O88*C88 -> 0.44801602 | V88: =2*(O88-G88)*(1-O88)*O88*D88 -> 0.30192384 | W88: =2*(O88-G88)*(1-O88)*O88*E88 -> 0.14609218 | X88: =2*(O88-G88)*(1-O88)*O88*F88 -> 0.019478957
B89: 5 | C89: 5 | D89: 3.6 | E89: 1.4 | F89: 0.2 | G89: 0 | H89: =IF(G89=P89, 1, 0) -> 1 | I89: =I88-0.1*T88 -> 0.30135966 | J89: =J88-0.1*U88 -> -0.40532425 | K89: =K88-0.1*V88 -> -0.18231283 | L89: =L88-0.1*W88 -> 0.41441338 | M89: =M88-0.1*X88 -> 0.53534488 | N89: =I89+J89*C89+K89*D89+L89*E89+F89*M89 -> -1.6943401 | O89: =1/(1+EXP(-N89)) -> 0.15520593 | P89: =IF(O89>0.5,1,0) -> 0 | Q89: =O89-G89 -> 0.15520593 | R89: =Q89^2 -> 0.024088882 | T89: =2*(O89-G89)*(1-O89)*O89 -> 0.040700288 | U89: =2*(O89-G89)*(1-O89)*O89*C89 -> 0.20350144 | V89: =2*(O89-G89)*(1-O89)*O89*D89 -> 0.14652104 | W89: =2*(O89-G89)*(1-O89)*O89*E89 -> 0.056980404 | X89: =2*(O89-G89)*(1-O89)*O89*F89 -> 0.0081400577
B90: 6 | C90: 5.4 | D90: 3.9 | E90: 1.7 | F90: 0.4 | G90: 0 | H90: =IF(G90=P90, 1, 0) -> 1 | I90: =I89-0.1*T89 -> 0.29728964 | J90: =J89-0.1*U89 -> -0.42567439 | K90: =K89-0.1*V89 -> -0.19696493 | L90: =L89-0.1*W89 -> 0.40871534 | M90: =M89-0.1*X89 -> 0.53453087 | N90: =I90+J90*C90+K90*D90+L90*E90+F90*M90 -> -1.8608869 | O90: =1/(1+EXP(-N90)) -> 0.13459971 | P90: =IF(O90>0.5,1,0) -> 0 | Q90: =O90-G90 -> 0.13459971 | R90: =Q90^2 -> 0.018117082 | T90: =2*(O90-G90)*(1-O90)*O90 -> 0.031357056 | U90: =2*(O90-G90)*(1-O90)*O90*C90 -> 0.1693281 | V90: =2*(O90-G90)*(1-O90)*O90*D90 -> 0.12229252 | W90: =2*(O90-G90)*(1-O90)*O90*E90 -> 0.053306995 | X90: =2*(O90-G90)*(1-O90)*O90*F90 -> 0.012542822
B91: 7 | C91: 4.6 | D91: 3.4 | E91: 1.4 | F91: 0.3 | G91: 0 | H91: =IF(G91=P91, 1, 0) -> 1 | I91: =I90-0.1*T90 -> 0.29415393 | J91: =J90-0.1*U90 -> -0.4426072 | K91: =K90-0.1*V90 -> -0.20919419 | L91: =L90-0.1*W90 -> 0.40338464 | M91: =M90-0.1*X90 -> 0.53327659 | N91: =I91+J91*C91+K91*D91+L91*E91+F91*M91 -> -1.728378 | O91: =1/(1+EXP(-N91)) -> 0.15079517 | P91: =IF(O91>0.5,1,0) -> 0 | Q91: =O91-G91 -> 0.15079517 | R91: =Q91^2 -> 0.022739184 | T91: =2*(O91-G91)*(1-O91)*O91 -> 0.03862045 | U91: =2*(O91-G91)*(1-O91)*O91*C91 -> 0.17765407 | V91: =2*(O91-G91)*(1-O91)*O91*D91 -> 0.13130953 | W91: =2*(O91-G91)*(1-O91)*O91*E91 -> 0.054068631 | X91: =2*(O91-G91)*(1-O91)*O91*F91 -> 0.011586135
B92: 8 | C92: 5 | D92: 3.4 | E92: 1.5 | F92: 0.2 | G92: 0 | H92: =IF(G92=P92, 1, 0) -> 1 | I92: =I91-0.1*T91 -> 0.29029189 | J92: =J91-0.1*U91 -> -0.46037261 | K92: =K91-0.1*V91 -> -0.22232514 | L92: =L91-0.1*W91 -> 0.39797777 | M92: =M91-0.1*X91 -> 0.53211798 | N92: =I92+J92*C92+K92*D92+L92*E92+F92*M92 -> -2.0640864 | O92: =1/(1+EXP(-N92)) -> 0.11263675 | P92: =IF(O92>0.5,1,0) -> 0 | Q92: =O92-G92 -> 0.11263675 | R92: =Q92^2 -> 0.012687038 | T92: =2*(O92-G92)*(1-O92)*O92 -> 0.022516022 | U92: =2*(O92-G92)*(1-O92)*O92*C92 -> 0.11258011 | V92: =2*(O92-G92)*(1-O92)*O92*D92 -> 0.076554475 | W92: =2*(O92-G92)*(1-O92)*O92*E92 -> 0.033774033 | X92: =2*(O92-G92)*(1-O92)*O92*F92 -> 0.0045032044
B93: 9 | C93: 4.4 | D93: 2.9 | E93: 1.4 | F93: 0.2 | G93: 0 | H93: =IF(G93=P93, 1, 0) -> 1 | I93: =I92-0.1*T92 -> 0.28804028 | J93: =J92-0.1*U92 -> -0.47163062 | K93: =K92-0.1*V92 -> -0.22998059 | L93: =L92-0.1*W92 -> 0.39460037 | M93: =M92-0.1*X92 -> 0.53166766 | N93: =I93+J93*C93+K93*D93+L93*E93+F93*M93 -> -1.7953041 | O93: =1/(1+EXP(-N93)) -> 0.14242366 | P93: =IF(O93>0.5,1,0) -> 0 | Q93: =O93-G93 -> 0.14242366 | R93: =Q93^2 -> 0.020284498 | T93: =2*(O93-G93)*(1-O93)*O93 -> 0.034791011 | U93: =2*(O93-G93)*(1-O93)*O93*C93 -> 0.15308045 | V93: =2*(O93-G93)*(1-O93)*O93*D93 -> 0.10089393 | W93: =2*(O93-G93)*(1-O93)*O93*E93 -> 0.048707415 | X93: =2*(O93-G93)*(1-O93)*O93*F93 -> 0.0069582022
B94: 10 | C94: 4.9 | D94: 3.1 | E94: 1.5 | F94: 0.1 | G94: 0 | H94: =IF(G94=P94, 1, 0) -> 1 | I94: =I93-0.1*T93 -> 0.28456118 | J94: =J93-0.1*U93 -> -0.48693866 | K94: =K93-0.1*V93 -> -0.24006998 | L94: =L93-0.1*W93 -> 0.38972963 | M94: =M93-0.1*X93 -> 0.53097184 | N94: =I94+J94*C94+K94*D94+L94*E94+F94*M94 -> -2.2079636 | O94: =1/(1+EXP(-N94)) -> 0.099037633 | P94: =IF(O94>0.5,1,0) -> 0 | Q94: =O94-G94 -> 0.099037633 | R94: =Q94^2 -> 0.0098084527 | T94: =2*(O94-G94)*(1-O94)*O94 -> 0.017674093 | U94: =2*(O94-G94)*(1-O94)*O94*C94 -> 0.086603058 | V94: =2*(O94-G94)*(1-O94)*O94*D94 -> 0.05478969 | W94: =2*(O94-G94)*(1-O94)*O94*E94 -> 0.02651114 | X94: =2*(O94-G94)*(1-O94)*O94*F94 -> 0.0017674093
B95: 11 | C95: 5.4 | D95: 3.7 | E95: 1.5 | F95: 0.2 | G95: 0 | H95: =IF(G95=P95, 1, 0) -> 1 | I95: =I94-0.1*T94 -> 0.28279377 | J95: =J94-0.1*U94 -> -0.49559897 | K95: =K94-0.1*V94 -> -0.24554895 | L95: =L94-0.1*W94 -> 0.38707852 | M95: =M94-0.1*X94 -> 0.53079509 | N95: =I95+J95*C95+K95*D95+L95*E95+F95*M95 -> -2.615195 | O95: =1/(1+EXP(-N95)) -> 0.068166876 | P95: =IF(O95>0.5,1,0) -> 0 | Q95: =O95-G95 -> 0.068166876 | R95: =Q95^2 -> 0.004646723 | T95: =2*(O95-G95)*(1-O95)*O95 -> 0.0086599408 | U95: =2*(O95-G95)*(1-O95)*O95*C95 -> 0.046763681 | V95: =2*(O95-G95)*(1-O95)*O95*D95 -> 0.032041781 | W95: =2*(O95-G95)*(1-O95)*O95*E95 -> 0.012989911 | X95: =2*(O95-G95)*(1-O95)*O95*F95 -> 0.0017319882
B96: 12 | C96: 4.8 | D96: 3.4 | E96: 1.6 | F96: 0.2 | G96: 0 | H96: =IF(G96=P96, 1, 0) -> 1 | I96: =I95-0.1*T95 -> 0.28192778 | J96: =J95-0.1*U95 -> -0.50027534 | K96: =K95-0.1*V95 -> -0.24875313 | L96: =L95-0.1*W95 -> 0.38577952 | M96: =M95-0.1*X95 -> 0.5306219 | N96: =I96+J96*C96+K96*D96+L96*E96+F96*M96 -> -2.2417829 | O96: =1/(1+EXP(-N96)) -> 0.096060619 | P96: =IF(O96>0.5,1,0) -> 0 | Q96: =O96-G96 -> 0.096060619 | R96: =Q96^2 -> 0.0092276426 | T96: =2*(O96-G96)*(1-O96)*O96 -> 0.016682459 | U96: =2*(O96-G96)*(1-O96)*O96*C96 -> 0.080075803 | V96: =2*(O96-G96)*(1-O96)*O96*D96 -> 0.056720361 | W96: =2*(O96-G96)*(1-O96)*O96*E96 -> 0.026691934 | X96: =2*(O96-G96)*(1-O96)*O96*F96 -> 0.0033364918
B97: 13 | C97: 4.8 | D97: 3 | E97: 1.4 | F97: 0.1 | G97: 0 | H97: =IF(G97=P97, 1, 0) -> 1 | I97: =I96-0.1*T96 -> 0.28025953 | J97: =J96-0.1*U96 -> -0.50828292 | K97: =K96-0.1*V96 -> -0.25442516 | L97: =L96-0.1*W96 -> 0.38311033 | M97: =M96-0.1*X96 -> 0.53028825 | N97: =I97+J97*C97+K97*D97+L97*E97+F97*M97 -> -2.3333907 | O97: =1/(1+EXP(-N97)) -> 0.088395056 | P97: =IF(O97>0.5,1,0) -> 0 | Q97: =O97-G97 -> 0.088395056 | R97: =Q97^2 -> 0.0078136859 | T97: =2*(O97-G97)*(1-O97)*O97 -> 0.014245989 | U97: =2*(O97-G97)*(1-O97)*O97*C97 -> 0.068380749 | V97: =2*(O97-G97)*(1-O97)*O97*D97 -> 0.042737968 | W97: =2*(O97-G97)*(1-O97)*O97*E97 -> 0.019944385 | X97: =2*(O97-G97)*(1-O97)*O97*F97 -> 0.0014245989
... B163: 79 | C163: 5.6 | D163: 3 | E163: 4.1 | F163: 1.3 | G163: 1 | H163: =IF(G163=P163, 1, 0) -> 1 | I163: =I162-0.1*T162 -> 0.34197096 | J163: =J162-0.1*U162 -> -0.09597752 | K163: =K162-0.1*V162 -> -0.077536362 | L163: =L162-0.1*W162 -> 0.70519073 | M163: =M162-0.1*X162 -> 0.63578663 | N163: =I163+J163*C163+K163*D163+L163*E163+F163*M163 -> 3.2896924 | O163: =1/(1+EXP(-N163)) -> 0.9640735 | P163: =IF(O163>0.5,1,0) -> 1 | Q163: =O163-G163 -> -0.035926499 | R163: =Q163^2 -> 0.0012907133 | T163: =2*(O163-G163)*(1-O163)*O163 -> -0.002488685 | U163: =2*(O163-G163)*(1-O163)*O163*C163 -> -0.013936636 | V163: =2*(O163-G163)*(1-O163)*O163*D163 -> -0.0074660551 | W163: =2*(O163-G163)*(1-O163)*O163*E163 -> -0.010203609 | X163: =2*(O163-G163)*(1-O163)*O163*F163 -> -0.0032352905
B164: 80 | C164: 5.5 | D164: 2.5 | E164: 4 | F164: 1.3 | G164: 1 | H164: =IF(G164=P164, 1, 0) -> 1 | I164: =I163-0.1*T163 -> 0.34221983 | J164: =J163-0.1*U163 -> -0.094583856 | K164: =K163-0.1*V163 -> -0.076789756 | L164: =L163-0.1*W163 -> 0.70621109 | M164: =M163-0.1*X163 -> 0.63611016 | N164: =I164+J164*C164+K164*D164+L164*E164+F164*M164 -> 3.2818218 | O164: =1/(1+EXP(-N164)) -> 0.9637999 | P164: =IF(O164>0.5,1,0) -> 1 | Q164: =O164-G164 -> -0.0362001 | R164: =Q164^2 -> 0.0013104473 | S164: =AVERAGE(R85:R164) -> 0.037451914 | T164: =2*(O164-G164)*(1-O164)*O164 -> -0.0025260179 | U164: =2*(O164-G164)*(1-O164)*O164*C164 -> -0.013893098 | V164: =2*(O164-G164)*(1-O164)*O164*D164 -> -0.0063150447 | W164: =2*(O164-G164)*(1-O164)*O164*E164 -> -0.010104072 | X164: =2*(O164-G164)*(1-O164)*O164*F164 -> -0.0032838233
A165: epoch 3 | B165: 1 | C165: 5.1 | D165: 3.5 | E165: 1.4 | F165: 0.2 | G165: 0 | H165: =IF(G165=P165, 1, 0) -> 0 | I165: =I164-0.1*T164 -> 0.34247243 | J165: =J164-0.1*U164 -> -0.093194546 | K165: =K164-0.1*V164 -> -0.076158252 | L165: =L164-0.1*W164 -> 0.7072215 | M165: =M164-0.1*X164 -> 0.63643854 | N165: =I165+J165*C165+K165*D165+L165*E165+F165*M165 -> 0.71802417 | O165: =1/(1+EXP(-N165)) -> 0.67217178 | P165: =IF(O165>0.5,1,0) -> 1 | Q165: =O165-G165 -> 0.67217178 | R165: =Q165^2 -> 0.4518149 | T165: =2*(O165-G165)*(1-O165)*O165 -> 0.29623535 | U165: =2*(O165-G165)*(1-O165)*O165*C165 -> 1.5108003 | V165: =2*(O165-G165)*(1-O165)*O165*D165 -> 1.0368237 | W165: =2*(O165-G165)*(1-O165)*O165*E165 -> 0.41472949 | X165: =2*(O165-G165)*(1-O165)*O165*F165 -> 0.05924707
B166: 2 | C166: 4.9 | D166: 3 | E166: 1.4 | F166: 0.2 | G166: 0 | H166: =IF(G166=P166, 1, 0) -> 1 | I166: =I165-0.1*T165 -> 0.3128489 | J166: =J165-0.1*U165 -> -0.24427457 | K166: =K165-0.1*V165 -> -0.17984062 | L166: =L165-0.1*W165 -> 0.66574855 | M166: =M165-0.1*X165 -> 0.63051384 | N166: =I166+J166*C166+K166*D166+L166*E166+F166*M166 -> -0.36546765 | O166: =1/(1+EXP(-N166)) -> 0.40963665 | P166: =IF(O166>0.5,1,0) -> 0 | Q166: =O166-G166 -> 0.40963665 | R166: =Q166^2 -> 0.16780218 | T166: =2*(O166-G166)*(1-O166)*O166 -> 0.19812852 | U166: =2*(O166-G166)*(1-O166)*O166*C166 -> 0.97082974 | V166: =2*(O166-G166)*(1-O166)*O166*D166 -> 0.59438556 | W166: =2*(O166-G166)*(1-O166)*O166*E166 -> 0.27737993 | X166: =2*(O166-G166)*(1-O166)*O166*F166 -> 0.039625704
B167: 3 | C167: 4.7 | D167: 3.2 | E167: 1.3 | F167: 0.2 | G167: 0 | H167: =IF(G167=P167, 1, 0) -> 1 | I167: =I166-0.1*T166 -> 0.29303605 | J167: =J166-0.1*U166 -> -0.34135755 | K167: =K166-0.1*V166 -> -0.23927918 | L167: =L166-0.1*W166 -> 0.63801056 | M167: =M166-0.1*X166 -> 0.62655127 | N167: =I167+J167*C167+K167*D167+L167*E167+F167*M167 -> -1.1223138 | O167: =1/(1+EXP(-N167)) -> 0.24558234 | P167: =IF(O167>0.5,1,0) -> 0 | Q167: =O167-G167 -> 0.24558234 | R167: =Q167^2 -> 0.060310687 | T167: =2*(O167-G167)*(1-O167)*O167 -> 0.090998895 | U167: =2*(O167-G167)*(1-O167)*O167*C167 -> 0.42769481 | V167: =2*(O167-G167)*(1-O167)*O167*D167 -> 0.29119646 | W167: =2*(O167-G167)*(1-O167)*O167*E167 -> 0.11829856 | X167: =2*(O167-G167)*(1-O167)*O167*F167 -> 0.018199779
B168: 4 | C168: 4.6 | D168: 3.1 | E168: 1.5 | F168: 0.2 | G168: 0 | H168: =IF(G168=P168, 1, 0) -> 1 | I168: =I167-0.1*T167 -> 0.28393616 | J168: =J167-0.1*U167 -> -0.38412703 | K168: =K167-0.1*V167 -> -0.26839883 | L168: =L167-0.1*W167 -> 0.6261807 | M168: =M167-0.1*X167 -> 0.62473129 | N168: =I168+J168*C168+K168*D168+L168*E168+F168*M168 -> -1.2508672 | O168: =1/(1+EXP(-N168)) -> 0.22255005 | P168: =IF(O168>0.5,1,0) -> 0 | Q168: =O168-G168 -> 0.22255005 | R168: =Q168^2 -> 0.049528526 | T168: =2*(O168-G168)*(1-O168)*O168 -> 0.0770119 | U168: =2*(O168-G168)*(1-O168)*O168*C168 -> 0.35425474 | V168: =2*(O168-G168)*(1-O168)*O168*D168 -> 0.23873689 | W168: =2*(O168-G168)*(1-O168)*O168*E168 -> 0.11551785 | X168: =2*(O168-G168)*(1-O168)*O168*F168 -> 0.01540238
B169: 5 | C169: 5 | D169: 3.6 | E169: 1.4 | F169: 0.2 | G169: 0 | H169: =IF(G169=P169, 1, 0) -> 1 | I169: =I168-0.1*T168 -> 0.27623497 | J169: =J168-0.1*U168 -> -0.4195525 | K169: =K168-0.1*V168 -> -0.29227252 | L169: =L168-0.1*W168 -> 0.61462892 | M169: =M168-0.1*X168 -> 0.62319105 | N169: =I169+J169*C169+K169*D169+L169*E169+F169*M169 -> -1.8885899 | O169: =1/(1+EXP(-N169)) -> 0.13140533 | P169: =IF(O169>0.5,1,0) -> 0 | Q169: =O169-G169 -> 0.13140533 | R169: =Q169^2 -> 0.017267361 | T169: =2*(O169-G169)*(1-O169)*O169 -> 0.029996675 | U169: =2*(O169-G169)*(1-O169)*O169*C169 -> 0.14998338 | V169: =2*(O169-G169)*(1-O169)*O169*D169 -> 0.10798803 | W169: =2*(O169-G169)*(1-O169)*O169*E169 -> 0.041995345 | X169: =2*(O169-G169)*(1-O169)*O169*F169 -> 0.005999335
B170: 6 | C170: 5.4 | D170: 3.9 | E170: 1.7 | F170: 0.4 | G170: 0 | H170: =IF(G170=P170, 1, 0) -> 1 | I170: =I169-0.1*T169 -> 0.2732353 | J170: =J169-0.1*U169 -> -0.43455084 | K170: =K169-0.1*V169 -> -0.30307132 | L170: =L169-0.1*W169 -> 0.61042938 | M170: =M169-0.1*X169 -> 0.62259112 | N170: =I170+J170*C170+K170*D170+L170*E170+F170*M170 -> -1.968551 | O170: =1/(1+EXP(-N170)) -> 0.12254461 | P170: =IF(O170>0.5,1,0) -> 0 | Q170: =O170-G170 -> 0.12254461 | R170: =Q170^2 -> 0.015017181 | T170: =2*(O170-G170)*(1-O170)*O170 -> 0.026353814 | U170: =2*(O170-G170)*(1-O170)*O170*C170 -> 0.14231059 | V170: =2*(O170-G170)*(1-O170)*O170*D170 -> 0.10277987 | W170: =2*(O170-G170)*(1-O170)*O170*E170 -> 0.044801483 | X170: =2*(O170-G170)*(1-O170)*O170*F170 -> 0.010541525
B171: 7 | C171: 4.6 | D171: 3.4 | E171: 1.4 | F171: 0.3 | G171: 0 | H171: =IF(G171=P171, 1, 0) -> 1 | I171: =I170-0.1*T170 -> 0.27059992 | J171: =J170-0.1*U170 -> -0.4487819 | K171: =K170-0.1*V170 -> -0.31334931 | L171: =L170-0.1*W170 -> 0.60594923 | M171: =M170-0.1*X170 -> 0.62153696 | N171: =I171+J171*C171+K171*D171+L171*E171+F171*M171 -> -1.8243944 | O171: =1/(1+EXP(-N171)) -> 0.13890741 | P171: =IF(O171>0.5,1,0) -> 0 | Q171: =O171-G171 -> 0.13890741 | R171: =Q171^2 -> 0.019295268 | T171: =2*(O171-G171)*(1-O171)*O171 -> 0.033230025 | U171: =2*(O171-G171)*(1-O171)*O171*C171 -> 0.15285812 | V171: =2*(O171-G171)*(1-O171)*O171*D171 -> 0.11298209 | W171: =2*(O171-G171)*(1-O171)*O171*E171 -> 0.046522035 | X171: =2*(O171-G171)*(1-O171)*O171*F171 -> 0.0099690075
...

Sheet SLP-Validation
I2: in validation, bias and teta are obtained from training for each epoch
G4: Setosa = 0 | I4: Learning Rate | K4: 0.1
G5: Versicolor = 1 | H5: Apakah prediksi sama dengan label aslinya? | I5: Bobot bias | N5: dot product | O5: Sigmoid | P5: Prediksi | Q5: error | R5: Sum Square Error | S5: Rata-rata Sum Square Error | T5: dbias | U5: dteta1 | V5: dteta2 | W5: dteta3 | X5: dteta4
A6: EPOCH | B6: No | C6: X1 | D6: X2 | E6: X3 | F6: X4 | G6: TARGET | I6: bias | J6: teta1 | K6: teta2 | L6: teta 3 | M6: teta4 | N6: z | O6: g(z)
A7: epoch1 | B7: 1 | C7: {=IF($B7<=10, INDEX(Data!$A:$A,40+$B7), INDEX(Data!$A:$A,80+$B7))} -> 5 | D7: {=IF($B7<=10, INDEX(Data!$B:$B,40+$B7), INDEX(Data!$B:$B,80+$B7))} -> 3.5 | E7: {=IF($B7<=10, INDEX(Data!$C:$C,40+$B7), INDEX(Data!$C:$C,80+$B7))} -> 1.3 | F7: {=IF($B7<=10, INDEX(Data!$D:$D,40+$B7), INDEX(Data!$D:$D,80+$B7))} -> 0.3 | G7: {=IF(INDEX(Data!$E:$E,IF($B7<=10,40+$B7,80+$B7))="Iris-setosa",0,1)} -> 0 | H7: =IF(G7=P7, 1, 0) -> 0 | I7: ='SLP-Training'!I84 -> 0.38006952 | J7: ='SLP-Training'!J84 -> -0.020599416 | K7: ='SLP-Training'!K84 -> 0.070780062 | L7: ='SLP-Training'!L84 -> 0.52338294 | M7: ='SLP-Training'!M84 -> 0.55079359 | N7: =I7+J7*C7+K7*D7+L7*E7+F7*M7 -> 1.3704386 | O7: =1/(1+EXP(-N7)) -> 0.797451 | P7: =IF(O7>0.5,1,0) -> 1 | Q7: =O7-G7 -> 0.797451 | R7: =Q7^2 -> 0.6359281 | T7: =2*(O7-G7)*(1-O7)*O7 -> 0.2576132 | U7: =2*(O7-G7)*(1-O7)*O7*C7 -> 1.288066 | V7: =2*(O7-G7)*(1-O7)*O7*D7 -> 0.9016462 | W7: =2*(O7-G7)*(1-O7)*O7*E7 -> 0.33489716 | X7: =2*(O7-G7)*(1-O7)*O7*F7 -> 0.07728396
B8: 2 | C8: {=IF($B8<=10, INDEX(Data!$A:$A,40+$B8), INDEX(Data!$A:$A,80+$B8))} -> 4.5 | D8: {=IF($B8<=10, INDEX(Data!$B:$B,40+$B8), INDEX(Data!$B:$B,80+$B8))} -> 2.3 | E8: {=IF($B8<=10, INDEX(Data!$C:$C,40+$B8), INDEX(Data!$C:$C,80+$B8))} -> 1.3 | F8: {=IF($B8<=10, INDEX(Data!$D:$D,40+$B8), INDEX(Data!$D:$D,80+$B8))} -> 0.3 | G8: {=IF(INDEX(Data!$E:$E,IF($B8<=10,40+$B8,80+$B8))="Iris-setosa",0,1)} -> 0 | H8: =IF(G8=P8, 1, 0) -> 0 | I8: =I7-$K$4*T7 -> 0.3543082 | J8: =J7-$K$4*U7 -> -0.14940602 | K8: =K7-$K$4*V7 -> -0.019384558 | L8: =L7-$K$4*W7 -> 0.48989322 | M8: =M7-$K$4*X7 -> 0.54306519 | N8: =I8+J8*C8+K8*D8+L8*E8+F8*M8 -> 0.43717739 | O8: =1/(1+EXP(-N8)) -> 0.60758625 | P8: =IF(O8>0.5,1,0) -> 1 | Q8: =O8-G8 -> 0.60758625 | R8: =Q8^2 -> 0.36916106 | T8: =2*(O8-G8)*(1-O8)*O8 -> 0.28972775 | U8: =2*(O8-G8)*(1-O8)*O8*C8 -> 1.3037749 | V8: =2*(O8-G8)*(1-O8)*O8*D8 -> 0.66637382 | W8: =2*(O8-G8)*(1-O8)*O8*E8 -> 0.37664607 | X8: =2*(O8-G8)*(1-O8)*O8*F8 -> 0.086918324
B9: 3 | C9: {=IF($B9<=10, INDEX(Data!$A:$A,40+$B9), INDEX(Data!$A:$A,80+$B9))} -> 4.4 | D9: {=IF($B9<=10, INDEX(Data!$B:$B,40+$B9), INDEX(Data!$B:$B,80+$B9))} -> 3.2 | E9: {=IF($B9<=10, INDEX(Data!$C:$C,40+$B9), INDEX(Data!$C:$C,80+$B9))} -> 1.3 | F9: {=IF($B9<=10, INDEX(Data!$D:$D,40+$B9), INDEX(Data!$D:$D,80+$B9))} -> 0.2 | G9: {=IF(INDEX(Data!$E:$E,IF($B9<=10,40+$B9,80+$B9))="Iris-setosa",0,1)} -> 0 | H9: =IF(G9=P9, 1, 0) -> 1 | I9: =I8-$K$4*T8 -> 0.32533543 | J9: =J8-$K$4*U8 -> -0.2797835 | K9: =K8-$K$4*V8 -> -0.08602194 | L9: =L8-$K$4*W8 -> 0.45222861 | M9: =M8-$K$4*X8 -> 0.53437336 | N9: =I9+J9*C9+K9*D9+L9*E9+F9*M9 -> -0.48621032 | O9: =1/(1+EXP(-N9)) -> 0.38078673 | P9: =IF(O9>0.5,1,0) -> 0 | Q9: =O9-G9 -> 0.38078673 | R9: =Q9^2 -> 0.14499853 | T9: =2*(O9-G9)*(1-O9)*O9 -> 0.17957003 | U9: =2*(O9-G9)*(1-O9)*O9*C9 -> 0.79010813 | V9: =2*(O9-G9)*(1-O9)*O9*D9 -> 0.57462409 | W9: =2*(O9-G9)*(1-O9)*O9*E9 -> 0.23344104 | X9: =2*(O9-G9)*(1-O9)*O9*F9 -> 0.035914006
B10: 4 | C10: {=IF($B10<=10, INDEX(Data!$A:$A,40+$B10), INDEX(Data!$A:$A,80+$B10))} -> 5 | D10: {=IF($B10<=10, INDEX(Data!$B:$B,40+$B10), INDEX(Data!$B:$B,80+$B10))} -> 3.5 | E10: {=IF($B10<=10, INDEX(Data!$C:$C,40+$B10), INDEX(Data!$C:$C,80+$B10))} -> 1.6 | F10: {=IF($B10<=10, INDEX(Data!$D:$D,40+$B10), INDEX(Data!$D:$D,80+$B10))} -> 0.6 | G10: {=IF(INDEX(Data!$E:$E,IF($B10<=10,40+$B10,80+$B10))="Iris-setosa",0,1)} -> 0 | H10: =IF(G10=P10, 1, 0) -> 1 | I10: =I9-$K$4*T9 -> 0.30737843 | J10: =J9-$K$4*U9 -> -0.35879431 | K10: =K9-$K$4*V9 -> -0.14348435 | L10: =L9-$K$4*W9 -> 0.42888451 | M10: =M9-$K$4*X9 -> 0.53078196 | N10: =I10+J10*C10+K10*D10+L10*E10+F10*M10 -> -0.98410398 | O10: =1/(1+EXP(-N10)) -> 0.27207822 | P10: =IF(O10>0.5,1,0) -> 0 | Q10: =O10-G10 -> 0.27207822 | R10: =Q10^2 -> 0.07402656 | T10: =2*(O10-G10)*(1-O10)*O10 -> 0.10777109 | U10: =2*(O10-G10)*(1-O10)*O10*C10 -> 0.53885545 | V10: =2*(O10-G10)*(1-O10)*O10*D10 -> 0.37719881 | W10: =2*(O10-G10)*(1-O10)*O10*E10 -> 0.17243374 | X10: =2*(O10-G10)*(1-O10)*O10*F10 -> 0.064662654
B11: 5 | C11: {=IF($B11<=10, INDEX(Data!$A:$A,40+$B11), INDEX(Data!$A:$A,80+$B11))} -> 5.1 | D11: {=IF($B11<=10, INDEX(Data!$B:$B,40+$B11), INDEX(Data!$B:$B,80+$B11))} -> 3.8 | E11: {=IF($B11<=10, INDEX(Data!$C:$C,40+$B11), INDEX(Data!$C:$C,80+$B11))} -> 1.9 | F11: {=IF($B11<=10, INDEX(Data!$D:$D,40+$B11), INDEX(Data!$D:$D,80+$B11))} -> 0.4 | G11: {=IF(INDEX(Data!$E:$E,IF($B11<=10,40+$B11,80+$B11))="Iris-setosa",0,1)} -> 0 | H11: =IF(G11=P11, 1, 0) -> 1 | I11: =I10-$K$4*T10 -> 0.29660132 | J11: =J10-$K$4*U10 -> -0.41267986 | K11: =K10-$K$4*V10 -> -0.18120423 | L11: =L10-$K$4*W10 -> 0.41164113 | M11: =M10-$K$4*X10 -> 0.5243157 | N11: =I11+J11*C11+K11*D11+L11*E11+F11*M11 -> -1.5047976 | O11: =1/(1+EXP(-N11)) -> 0.18171107 | P11: =IF(O11>0.5,1,0) -> 0 | Q11: =O11-G11 -> 0.18171107 | R11: =Q11^2 -> 0.033018912 | T11: =2*(O11-G11)*(1-O11)*O11 -> 0.05403802 | U11: =2*(O11-G11)*(1-O11)*O11*C11 -> 0.2755939 | V11: =2*(O11-G11)*(1-O11)*O11*D11 -> 0.20534448 | W11: =2*(O11-G11)*(1-O11)*O11*E11 -> 0.10267224 | X11: =2*(O11-G11)*(1-O11)*O11*F11 -> 0.021615208
B12: 6 | C12: {=IF($B12<=10, INDEX(Data!$A:$A,40+$B12), INDEX(Data!$A:$A,80+$B12))} -> 4.8 | D12: {=IF($B12<=10, INDEX(Data!$B:$B,40+$B12), INDEX(Data!$B:$B,80+$B12))} -> 3 | E12: {=IF($B12<=10, INDEX(Data!$C:$C,40+$B12), INDEX(Data!$C:$C,80+$B12))} -> 1.4 | F12: {=IF($B12<=10, INDEX(Data!$D:$D,40+$B12), INDEX(Data!$D:$D,80+$B12))} -> 0.3 | G12: {=IF(INDEX(Data!$E:$E,IF($B12<=10,40+$B12,80+$B12))="Iris-setosa",0,1)} -> 0 | H12: =IF(G12=P12, 1, 0) -> 1 | I12: =I11-$K$4*T11 -> 0.29119751 | J12: =J11-$K$4*U11 -> -0.44023925 | K12: =K11-$K$4*V11 -> -0.20173868 | L12: =L11-$K$4*W11 -> 0.40137391 | M12: =M11-$K$4*X11 -> 0.52215418 | N12: =I12+J12*C12+K12*D12+L12*E12+F12*M12 -> -1.7085972 | O12: =1/(1+EXP(-N12)) -> 0.15334575 | P12: =IF(O12>0.5,1,0) -> 0 | Q12: =O12-G12 -> 0.15334575 | R12: =Q12^2 -> 0.02351492 | T12: =2*(O12-G12)*(1-O12)*O12 -> 0.039818014 | U12: =2*(O12-G12)*(1-O12)*O12*C12 -> 0.19112647 | V12: =2*(O12-G12)*(1-O12)*O12*D12 -> 0.11945404 | W12: =2*(O12-G12)*(1-O12)*O12*E12 -> 0.05574522 | X12: =2*(O12-G12)*(1-O12)*O12*F12 -> 0.011945404
B13: 7 | C13: {=IF($B13<=10, INDEX(Data!$A:$A,40+$B13), INDEX(Data!$A:$A,80+$B13))} -> 5.1 | D13: {=IF($B13<=10, INDEX(Data!$B:$B,40+$B13), INDEX(Data!$B:$B,80+$B13))} -> 3.8 | E13: {=IF($B13<=10, INDEX(Data!$C:$C,40+$B13), INDEX(Data!$C:$C,80+$B13))} -> 1.6 | F13: {=IF($B13<=10, INDEX(Data!$D:$D,40+$B13), INDEX(Data!$D:$D,80+$B13))} -> 0.2 | G13: {=IF(INDEX(Data!$E:$E,IF($B13<=10,40+$B13,80+$B13))="Iris-setosa",0,1)} -> 0 | H13: =IF(G13=P13, 1, 0) -> 1 | I13: =I12-$K$4*T12 -> 0.28721571 | J13: =J12-$K$4*U12 -> -0.4593519 | K13: =K12-$K$4*V12 -> -0.21368408 | L13: =L12-$K$4*W12 -> 0.39579939 | M13: =M12-$K$4*X12 -> 0.52095964 | N13: =I13+J13*C13+K13*D13+L13*E13+F13*M13 -> -2.1300075 | O13: =1/(1+EXP(-N13)) -> 0.10621428 | P13: =IF(O13>0.5,1,0) -> 0 | Q13: =O13-G13 -> 0.10621428 | R13: =Q13^2 -> 0.011281473 | T13: =2*(O13-G13)*(1-O13)*O13 -> 0.020166438 | U13: =2*(O13-G13)*(1-O13)*O13*C13 -> 0.10284884 | V13: =2*(O13-G13)*(1-O13)*O13*D13 -> 0.076632466 | W13: =2*(O13-G13)*(1-O13)*O13*E13 -> 0.032266301 | X13: =2*(O13-G13)*(1-O13)*O13*F13 -> 0.0040332877
B14: 8 | C14: {=IF($B14<=10, INDEX(Data!$A:$A,40+$B14), INDEX(Data!$A:$A,80+$B14))} -> 4.6 | D14: {=IF($B14<=10, INDEX(Data!$B:$B,40+$B14), INDEX(Data!$B:$B,80+$B14))} -> 3.2 | E14: {=IF($B14<=10, INDEX(Data!$C:$C,40+$B14), INDEX(Data!$C:$C,80+$B14))} -> 1.4 | F14: {=IF($B14<=10, INDEX(Data!$D:$D,40+$B14), INDEX(Data!$D:$D,80+$B14))} -> 0.2 | G14: {=IF(INDEX(Data!$E:$E,IF($B14<=10,40+$B14,80+$B14))="Iris-setosa",0,1)} -> 0 | H14: =IF(G14=P14, 1, 0) -> 1 | I14: =I13-$K$4*T13 -> 0.28519907 | J14: =J13-$K$4*U13 -> -0.46963678 | K14: =K13-$K$4*V13 -> -0.22134733 | L14: =L13-$K$4*W13 -> 0.39257276 | M14: =M13-$K$4*X13 -> 0.52055631 | N14: =I14+J14*C14+K14*D14+L14*E14+F14*M14 -> -1.9297285 | O14: =1/(1+EXP(-N14)) -> 0.12678064 | P14: =IF(O14>0.5,1,0) -> 0 | Q14: =O14-G14 -> 0.12678064 | R14: =Q14^2 -> 0.016073331 | T14: =2*(O14-G14)*(1-O14)*O14 -> 0.028071087 | U14: =2*(O14-G14)*(1-O14)*O14*C14 -> 0.129127 | V14: =2*(O14-G14)*(1-O14)*O14*D14 -> 0.089827478 | W14: =2*(O14-G14)*(1-O14)*O14*E14 -> 0.039299521 | X14: =2*(O14-G14)*(1-O14)*O14*F14 -> 0.0056142174
B15: 9 | C15: {=IF($B15<=10, INDEX(Data!$A:$A,40+$B15), INDEX(Data!$A:$A,80+$B15))} -> 5.3 | D15: {=IF($B15<=10, INDEX(Data!$B:$B,40+$B15), INDEX(Data!$B:$B,80+$B15))} -> 3.7 | E15: {=IF($B15<=10, INDEX(Data!$C:$C,40+$B15), INDEX(Data!$C:$C,80+$B15))} -> 1.5 | F15: {=IF($B15<=10, INDEX(Data!$D:$D,40+$B15), INDEX(Data!$D:$D,80+$B15))} -> 0.2 | G15: {=IF(INDEX(Data!$E:$E,IF($B15<=10,40+$B15,80+$B15))="Iris-setosa",0,1)} -> 0 | H15: =IF(G15=P15, 1, 0) -> 1 | I15: =I14-$K$4*T14 -> 0.28239196 | J15: =J14-$K$4*U14 -> -0.48254948 | K15: =K14-$K$4*V14 -> -0.23033008 | L15: =L14-$K$4*W14 -> 0.38864281 | M15: =M14-$K$4*X14 -> 0.51999488 | N15: =I15+J15*C15+K15*D15+L15*E15+F15*M15 -> -2.4403784 | O15: =1/(1+EXP(-N15)) -> 0.080145012 | P15: =IF(O15>0.5,1,0) -> 0 | Q15: =O15-G15 -> 0.080145012 | R15: =Q15^2 -> 0.006423223 | T15: =2*(O15-G15)*(1-O15)*O15 -> 0.011816867 | U15: =2*(O15-G15)*(1-O15)*O15*C15 -> 0.062629398 | V15: =2*(O15-G15)*(1-O15)*O15*D15 -> 0.04372241 | W15: =2*(O15-G15)*(1-O15)*O15*E15 -> 0.017725301 | X15: =2*(O15-G15)*(1-O15)*O15*F15 -> 0.0023633735
B16: 10 | C16: {=IF($B16<=10, INDEX(Data!$A:$A,40+$B16), INDEX(Data!$A:$A,80+$B16))} -> 5 | D16: {=IF($B16<=10, INDEX(Data!$B:$B,40+$B16), INDEX(Data!$B:$B,80+$B16))} -> 3.3 | E16: {=IF($B16<=10, INDEX(Data!$C:$C,40+$B16), INDEX(Data!$C:$C,80+$B16))} -> 1.4 | F16: {=IF($B16<=10, INDEX(Data!$D:$D,40+$B16), INDEX(Data!$D:$D,80+$B16))} -> 0.2 | G16: {=IF(INDEX(Data!$E:$E,IF($B16<=10,40+$B16,80+$B16))="Iris-setosa",0,1)} -> 0 | H16: =IF(G16=P16, 1, 0) -> 1 | I16: =I15-$K$4*T15 -> 0.28121027 | J16: =J15-$K$4*U15 -> -0.48881242 | K16: =K15-$K$4*V15 -> -0.23470232 | L16: =L15-$K$4*W15 -> 0.38687028 | M16: =M15-$K$4*X15 -> 0.51975855 | N16: =I16+J16*C16+K16*D16+L16*E16+F16*M16 -> -2.2917994 | O16: =1/(1+EXP(-N16)) -> 0.091804414 | P16: =IF(O16>0.5,1,0) -> 0 | Q16: =O16-G16 -> 0.091804414 | R16: =Q16^2 -> 0.0084280504 | T16: =2*(O16-G16)*(1-O16)*O16 -> 0.015308636 | U16: =2*(O16-G16)*(1-O16)*O16*C16 -> 0.076543182 | V16: =2*(O16-G16)*(1-O16)*O16*D16 -> 0.0505185 | W16: =2*(O16-G16)*(1-O16)*O16*E16 -> 0.021432091 | X16: =2*(O16-G16)*(1-O16)*O16*F16 -> 0.0030617273
B17: 11 | C17: {=IF($B17<=10, INDEX(Data!$A:$A,40+$B17), INDEX(Data!$A:$A,80+$B17))} -> 5.5 | D17: {=IF($B17<=10, INDEX(Data!$B:$B,40+$B17), INDEX(Data!$B:$B,80+$B17))} -> 2.6 | E17: {=IF($B17<=10, INDEX(Data!$C:$C,40+$B17), INDEX(Data!$C:$C,80+$B17))} -> 4.4 | F17: {=IF($B17<=10, INDEX(Data!$D:$D,40+$B17), INDEX(Data!$D:$D,80+$B17))} -> 1.2 | G17: {=IF(INDEX(Data!$E:$E,IF($B17<=10,40+$B17,80+$B17))="Iris-setosa",0,1)} -> 1 | H17: =IF(G17=P17, 1, 0) -> 0 | I17: =I16-$K$4*T16 -> 0.27967941 | J17: =J16-$K$4*U16 -> -0.49646674 | K17: =K16-$K$4*V16 -> -0.23975417 | L17: =L16-$K$4*W16 -> 0.38472707 | M17: =M16-$K$4*X16 -> 0.51945237 | N17: =I17+J17*C17+K17*D17+L17*E17+F17*M17 -> -0.75810654 | O17: =1/(1+EXP(-N17)) -> 0.3190575 | P17: =IF(O17>0.5,1,0) -> 0 | Q17: =O17-G17 -> -0.6809425 | R17: =Q17^2 -> 0.46368269 | T17: =2*(O17-G17)*(1-O17)*O17 -> -0.29588288 | U17: =2*(O17-G17)*(1-O17)*O17*C17 -> -1.6273558 | V17: =2*(O17-G17)*(1-O17)*O17*D17 -> -0.76929548 | W17: =2*(O17-G17)*(1-O17)*O17*E17 -> -1.3018847 | X17: =2*(O17-G17)*(1-O17)*O17*F17 -> -0.35505945
B18: 12 | C18: {=IF($B18<=10, INDEX(Data!$A:$A,40+$B18), INDEX(Data!$A:$A,80+$B18))} -> 6.1 | D18: {=IF($B18<=10, INDEX(Data!$B:$B,40+$B18), INDEX(Data!$B:$B,80+$B18))} -> 3 | E18: {=IF($B18<=10, INDEX(Data!$C:$C,40+$B18), INDEX(Data!$C:$C,80+$B18))} -> 4.6 | F18: {=IF($B18<=10, INDEX(Data!$D:$D,40+$B18), INDEX(Data!$D:$D,80+$B18))} -> 1.4 | G18: {=IF(INDEX(Data!$E:$E,IF($B18<=10,40+$B18,80+$B18))="Iris-setosa",0,1)} -> 1 | H18: =IF(G18=P18, 1, 0) -> 1 | I18: =I17-$K$4*T17 -> 0.3092677 | J18: =J17-$K$4*U17 -> -0.33373116 | K18: =K17-$K$4*V17 -> -0.16282462 | L18: =L17-$K$4*W17 -> 0.51491553 | M18: =M17-$K$4*X17 -> 0.55495832 | N18: =I18+J18*C18+K18*D18+L18*E18+F18*M18 -> 0.93058689 | O18: =1/(1+EXP(-N18)) -> 0.71719434 | P18: =IF(O18>0.5,1,0) -> 1 | Q18: =O18-G18 -> -0.28280566 | R18: =Q18^2 -> 0.079979042 | T18: =2*(O18-G18)*(1-O18)*O18 -> -0.11472103 | U18: =2*(O18-G18)*(1-O18)*O18*C18 -> -0.6997983 | V18: =2*(O18-G18)*(1-O18)*O18*D18 -> -0.3441631 | W18: =2*(O18-G18)*(1-O18)*O18*E18 -> -0.52771675 | X18: =2*(O18-G18)*(1-O18)*O18*F18 -> -0.16060945
B19: 13 | C19: {=IF($B19<=10, INDEX(Data!$A:$A,40+$B19), INDEX(Data!$A:$A,80+$B19))} -> 5.8 | D19: {=IF($B19<=10, INDEX(Data!$B:$B,40+$B19), INDEX(Data!$B:$B,80+$B19))} -> 2.6 | E19: {=IF($B19<=10, INDEX(Data!$C:$C,40+$B19), INDEX(Data!$C:$C,80+$B19))} -> 4 | F19: {=IF($B19<=10, INDEX(Data!$D:$D,40+$B19), INDEX(Data!$D:$D,80+$B19))} -> 1.2 | G19: {=IF(INDEX(Data!$E:$E,IF($B19<=10,40+$B19,80+$B19))="Iris-setosa",0,1)} -> 1 | H19: =IF(G19=P19, 1, 0) -> 1 | I19: =I18-$K$4*T18 -> 0.3207398 | J19: =J18-$K$4*U18 -> -0.26375133 | K19: =K18-$K$4*V18 -> -0.12840831 | L19: =L18-$K$4*W18 -> 0.56768721 | M19: =M18-$K$4*X18 -> 0.57101926 | N19: =I19+J19*C19+K19*D19+L19*E19+F19*M19 -> 1.4130925 | O19: =1/(1+EXP(-N19)) -> 0.80425325 | P19: =IF(O19>0.5,1,0) -> 1 | Q19: =O19-G19 -> -0.19574675 | R19: =Q19^2 -> 0.038316791 | T19: =2*(O19-G19)*(1-O19)*O19 -> -0.061632807 | U19: =2*(O19-G19)*(1-O19)*O19*C19 -> -0.35747028 | V19: =2*(O19-G19)*(1-O19)*O19*D19 -> -0.1602453 | W19: =2*(O19-G19)*(1-O19)*O19*E19 -> -0.24653123 | X19: =2*(O19-G19)*(1-O19)*O19*F19 -> -0.073959369
... B25: 19 | C25: {=IF($B25<=10, INDEX(Data!$A:$A,40+$B25), INDEX(Data!$A:$A,80+$B25))} -> 5.1 | D25: {=IF($B25<=10, INDEX(Data!$B:$B,40+$B25), INDEX(Data!$B:$B,80+$B25))} -> 2.5 | E25: {=IF($B25<=10, INDEX(Data!$C:$C,40+$B25), INDEX(Data!$C:$C,80+$B25))} -> 3 | F25: {=IF($B25<=10, INDEX(Data!$D:$D,40+$B25), INDEX(Data!$D:$D,80+$B25))} -> 1.1 | G25: {=IF(INDEX(Data!$E:$E,IF($B25<=10,40+$B25,80+$B25))="Iris-setosa",0,1)} -> 1 | H25: =IF(G25=P25, 1, 0) -> 1 | I25: =I24-$K$4*T24 -> 0.33814504 | J25: =J24-$K$4*U24 -> -0.16755734 | K25: =K24-$K$4*V24 -> -0.083387157 | L25: =L24-$K$4*W24 -> 0.63448973 | M25: =M24-$K$4*X24 -> 0.5911431 | N25: =I25+J25*C25+K25*D25+L25*E25+F25*M25 -> 1.8288613 | O25: =1/(1+EXP(-N25)) -> 0.86162602 | P25: =IF(O25>0.5,1,0) -> 1 | Q25: =O25-G25 -> -0.13837398 | R25: =Q25^2 -> 0.019147358 | T25: =2*(O25-G25)*(1-O25)*O25 -> -0.032995723 | U25: =2*(O25-G25)*(1-O25)*O25*C25 -> -0.16827819 | V25: =2*(O25-G25)*(1-O25)*O25*D25 -> -0.082489309 | W25: =2*(O25-G25)*(1-O25)*O25*E25 -> -0.09898717 | X25: =2*(O25-G25)*(1-O25)*O25*F25 -> -0.036295296
B26: 20 | C26: {=IF($B26<=10, INDEX(Data!$A:$A,40+$B26), INDEX(Data!$A:$A,80+$B26))} -> 5.7 | D26: {=IF($B26<=10, INDEX(Data!$B:$B,40+$B26), INDEX(Data!$B:$B,80+$B26))} -> 2.8 | E26: {=IF($B26<=10, INDEX(Data!$C:$C,40+$B26), INDEX(Data!$C:$C,80+$B26))} -> 4.1 | F26: {=IF($B26<=10, INDEX(Data!$D:$D,40+$B26), INDEX(Data!$D:$D,80+$B26))} -> 1.3 | G26: {=IF(INDEX(Data!$E:$E,IF($B26<=10,40+$B26,80+$B26))="Iris-setosa",0,1)} -> 1 | H26: =IF(G26=P26, 1, 0) -> 1 | I26: =I25-$K$4*T25 -> 0.34144461 | J26: =J25-$K$4*U25 -> -0.15072952 | K26: =K25-$K$4*V25 -> -0.075138226 | L26: =L25-$K$4*W25 -> 0.64438845 | M26: =M25-$K$4*X25 -> 0.59477263 | N26: =I26+J26*C26+K26*D26+L26*E26+F26*M26 -> 2.6870964 | O26: =1/(1+EXP(-N26)) -> 0.93626092 | P26: =IF(O26>0.5,1,0) -> 1 | Q26: =O26-G26 -> -0.063739077 | R26: =Q26^2 -> 0.0040626699 | S26: =AVERAGE(R7:R26) -> 0.099677958 | T26: =2*(O26-G26)*(1-O26)*O26 -> -0.0076074382 | U26: =2*(O26-G26)*(1-O26)*O26*C26 -> -0.043362398 | V26: =2*(O26-G26)*(1-O26)*O26*D26 -> -0.021300827 | W26: =2*(O26-G26)*(1-O26)*O26*E26 -> -0.031190497 | X26: =2*(O26-G26)*(1-O26)*O26*F26 -> -0.0098896697
A27: epoch 2 | B27: 1 | C27: {=IF($B27<=10, INDEX(Data!$A:$A,40+$B27), INDEX(Data!$A:$A,80+$B27))} -> 5 | D27: {=IF($B27<=10, INDEX(Data!$B:$B,40+$B27), INDEX(Data!$B:$B,80+$B27))} -> 3.5 | E27: {=IF($B27<=10, INDEX(Data!$C:$C,40+$B27), INDEX(Data!$C:$C,80+$B27))} -> 1.3 | F27: {=IF($B27<=10, INDEX(Data!$D:$D,40+$B27), INDEX(Data!$D:$D,80+$B27))} -> 0.3 | G27: {=IF(INDEX(Data!$E:$E,IF($B27<=10,40+$B27,80+$B27))="Iris-setosa",0,1)} -> 0 | H27: =IF(G27=P27, 1, 0) -> 0 | I27: ='SLP-Training'!I164 -> 0.34221983 | J27: ='SLP-Training'!J164 -> -0.094583856 | K27: ='SLP-Training'!K164 -> -0.076789756 | L27: ='SLP-Training'!L164 -> 0.70621109 | M27: ='SLP-Training'!M164 -> 0.63611016 | N27: =I27+J27*C27+K27*D27+L27*E27+F27*M27 -> 0.70944387 | O27: =1/(1+EXP(-N27)) -> 0.67027826 | P27: =IF(O27>0.5,1,0) -> 1 | Q27: =O27-G27 -> 0.67027826 | R27: =Q27^2 -> 0.44927295 | T27: =2*(O27-G27)*(1-O27)*O27 -> 0.29627011 | U27: =2*(O27-G27)*(1-O27)*O27*C27 -> 1.4813506 | V27: =2*(O27-G27)*(1-O27)*O27*D27 -> 1.0369454 | W27: =2*(O27-G27)*(1-O27)*O27*E27 -> 0.38515115 | X27: =2*(O27-G27)*(1-O27)*O27*F27 -> 0.088881034
B28: 2 | C28: {=IF($B28<=10, INDEX(Data!$A:$A,40+$B28), INDEX(Data!$A:$A,80+$B28))} -> 4.5 | D28: {=IF($B28<=10, INDEX(Data!$B:$B,40+$B28), INDEX(Data!$B:$B,80+$B28))} -> 2.3 | E28: {=IF($B28<=10, INDEX(Data!$C:$C,40+$B28), INDEX(Data!$C:$C,80+$B28))} -> 1.3 | F28: {=IF($B28<=10, INDEX(Data!$D:$D,40+$B28), INDEX(Data!$D:$D,80+$B28))} -> 0.3 | G28: {=IF(INDEX(Data!$E:$E,IF($B28<=10,40+$B28,80+$B28))="Iris-setosa",0,1)} -> 0 | H28: =IF(G28=P28, 1, 0) -> 1 | I28: =I27-$K$4*T27 -> 0.31259282 | J28: =J27-$K$4*U27 -> -0.24271891 | K28: =K27-$K$4*V27 -> -0.1804843 | L28: =L27-$K$4*W27 -> 0.66769598 | M28: =M27-$K$4*X27 -> 0.62722206 | N28: =I28+J28*C28+K28*D28+L28*E28+F28*M28 -> -0.13858479 | O28: =1/(1+EXP(-N28)) -> 0.46540915 | P28: =IF(O28>0.5,1,0) -> 0 | Q28: =O28-G28 -> 0.46540915 | R28: =Q28^2 -> 0.21660567 | T28: =2*(O28-G28)*(1-O28)*O28 -> 0.23159082 | U28: =2*(O28-G28)*(1-O28)*O28*C28 -> 1.0421587 | V28: =2*(O28-G28)*(1-O28)*O28*D28 -> 0.5326589 | W28: =2*(O28-G28)*(1-O28)*O28*E28 -> 0.30106807 | X28: =2*(O28-G28)*(1-O28)*O28*F28 -> 0.069477247
B29: 3 | C29: {=IF($B29<=10, INDEX(Data!$A:$A,40+$B29), INDEX(Data!$A:$A,80+$B29))} -> 4.4 | D29: {=IF($B29<=10, INDEX(Data!$B:$B,40+$B29), INDEX(Data!$B:$B,80+$B29))} -> 3.2 | E29: {=IF($B29<=10, INDEX(Data!$C:$C,40+$B29), INDEX(Data!$C:$C,80+$B29))} -> 1.3 | F29: {=IF($B29<=10, INDEX(Data!$D:$D,40+$B29), INDEX(Data!$D:$D,80+$B29))} -> 0.2 | G29: {=IF(INDEX(Data!$E:$E,IF($B29<=10,40+$B29,80+$B29))="Iris-setosa",0,1)} -> 0 | H29: =IF(G29=P29, 1, 0) -> 1 | I29: =I28-$K$4*T28 -> 0.28943374 | J29: =J28-$K$4*U28 -> -0.34693478 | K29: =K28-$K$4*V28 -> -0.23375019 | L29: =L28-$K$4*W28 -> 0.63758917 | M29: =M28-$K$4*X28 -> 0.62027433 | N29: =I29+J29*C29+K29*D29+L29*E29+F29*M29 -> -1.0321591 | O29: =1/(1+EXP(-N29)) -> 0.26266573 | P29: =IF(O29>0.5,1,0) -> 0 | Q29: =O29-G29 -> 0.26266573 | R29: =Q29^2 -> 0.068993284 | T29: =2*(O29-G29)*(1-O29)*O29 -> 0.10174223 | U29: =2*(O29-G29)*(1-O29)*O29*C29 -> 0.4476658 | V29: =2*(O29-G29)*(1-O29)*O29*D29 -> 0.32557512 | W29: =2*(O29-G29)*(1-O29)*O29*E29 -> 0.13226489 | X29: =2*(O29-G29)*(1-O29)*O29*F29 -> 0.020348445
B30: 4 | C30: {=IF($B30<=10, INDEX(Data!$A:$A,40+$B30), INDEX(Data!$A:$A,80+$B30))} -> 5 | D30: {=IF($B30<=10, INDEX(Data!$B:$B,40+$B30), INDEX(Data!$B:$B,80+$B30))} -> 3.5 | E30: {=IF($B30<=10, INDEX(Data!$C:$C,40+$B30), INDEX(Data!$C:$C,80+$B30))} -> 1.6 | F30: {=IF($B30<=10, INDEX(Data!$D:$D,40+$B30), INDEX(Data!$D:$D,80+$B30))} -> 0.6 | G30: {=IF(INDEX(Data!$E:$E,IF($B30<=10,40+$B30,80+$B30))="Iris-setosa",0,1)} -> 0 | H30: =IF(G30=P30, 1, 0) -> 1 | I30: =I29-$K$4*T29 -> 0.27925952 | J30: =J29-$K$4*U29 -> -0.39170136 | K30: =K29-$K$4*V29 -> -0.2663077 | L30: =L29-$K$4*W29 -> 0.62436268 | M30: =M29-$K$4*X29 -> 0.61823949 | N30: =I30+J30*C30+K30*D30+L30*E30+F30*M30 -> -1.2414003 | O30: =1/(1+EXP(-N30)) -> 0.22419234 | P30: =IF(O30>0.5,1,0) -> 0 | Q30: =O30-G30 -> 0.22419234 | R30: =Q30^2 -> 0.050262207 | T30: =2*(O30-G30)*(1-O30)*O30 -> 0.077987609 | U30: =2*(O30-G30)*(1-O30)*O30*C30 -> 0.38993805 | V30: =2*(O30-G30)*(1-O30)*O30*D30 -> 0.27295663 | W30: =2*(O30-G30)*(1-O30)*O30*E30 -> 0.12478018 | X30: =2*(O30-G30)*(1-O30)*O30*F30 -> 0.046792566
B31: 5 | C31: {=IF($B31<=10, INDEX(Data!$A:$A,40+$B31), INDEX(Data!$A:$A,80+$B31))} -> 5.1 | D31: {=IF($B31<=10, INDEX(Data!$B:$B,40+$B31), INDEX(Data!$B:$B,80+$B31))} -> 3.8 | E31: {=IF($B31<=10, INDEX(Data!$C:$C,40+$B31), INDEX(Data!$C:$C,80+$B31))} -> 1.9 | F31: {=IF($B31<=10, INDEX(Data!$D:$D,40+$B31), INDEX(Data!$D:$D,80+$B31))} -> 0.4 | G31: {=IF(INDEX(Data!$E:$E,IF($B31<=10,40+$B31,80+$B31))="Iris-setosa",0,1)} -> 0 | H31: =IF(G31=P31, 1, 0) -> 1 | I31: =I30-$K$4*T30 -> 0.27146075 | J31: =J30-$K$4*U30 -> -0.43069517 | K31: =K30-$K$4*V30 -> -0.29360336 | L31: =L30-$K$4*W30 -> 0.61188466 | M31: =M30-$K$4*X30 -> 0.61356023 | N31: =I31+J31*C31+K31*D31+L31*E31+F31*M31 -> -1.6327724 | O31: =1/(1+EXP(-N31)) -> 0.16345092 | P31: =IF(O31>0.5,1,0) -> 0 | Q31: =O31-G31 -> 0.16345092 | R31: =Q31^2 -> 0.026716203 | T31: =2*(O31-G31)*(1-O31)*O31 -> 0.04469883 | U31: =2*(O31-G31)*(1-O31)*O31*C31 -> 0.22796404 | V31: =2*(O31-G31)*(1-O31)*O31*D31 -> 0.16985556 | W31: =2*(O31-G31)*(1-O31)*O31*E31 -> 0.084927778 | X31: =2*(O31-G31)*(1-O31)*O31*F31 -> 0.017879532
B32: 6 | C32: {=IF($B32<=10, INDEX(Data!$A:$A,40+$B32), INDEX(Data!$A:$A,80+$B32))} -> 4.8 | D32: {=IF($B32<=10, INDEX(Data!$B:$B,40+$B32), INDEX(Data!$B:$B,80+$B32))} -> 3 | E32: {=IF($B32<=10, INDEX(Data!$C:$C,40+$B32), INDEX(Data!$C:$C,80+$B32))} -> 1.4 | F32: {=IF($B32<=10, INDEX(Data!$D:$D,40+$B32), INDEX(Data!$D:$D,80+$B32))} -> 0.3 | G32: {=IF(INDEX(Data!$E:$E,IF($B32<=10,40+$B32,80+$B32))="Iris-setosa",0,1)} -> 0 | H32: =IF(G32=P32, 1, 0) -> 1 | I32: =I31-$K$4*T31 -> 0.26699087 | J32: =J31-$K$4*U31 -> -0.45349157 | K32: =K31-$K$4*V31 -> -0.31058892 | L32: =L31-$K$4*W31 -> 0.60339188 | M32: =M31-$K$4*X31 -> 0.61177228 | N32: =I32+J32*C32+K32*D32+L32*E32+F32*M32 -> -1.8132551 | O32: =1/(1+EXP(-N32)) -> 0.14024518 | P32: =IF(O32>0.5,1,0) -> 0 | Q32: =O32-G32 -> 0.14024518 | R32: =Q32^2 -> 0.01966871 | T32: =2*(O32-G32)*(1-O32)*O32 -> 0.033820536 | U32: =2*(O32-G32)*(1-O32)*O32*C32 -> 0.16233857 | V32: =2*(O32-G32)*(1-O32)*O32*D32 -> 0.10146161 | W32: =2*(O32-G32)*(1-O32)*O32*E32 -> 0.04734875 | X32: =2*(O32-G32)*(1-O32)*O32*F32 -> 0.010146161
B33: 7 | C33: {=IF($B33<=10, INDEX(Data!$A:$A,40+$B33), INDEX(Data!$A:$A,80+$B33))} -> 5.1 | D33: {=IF($B33<=10, INDEX(Data!$B:$B,40+$B33), INDEX(Data!$B:$B,80+$B33))} -> 3.8 | E33: {=IF($B33<=10, INDEX(Data!$C:$C,40+$B33), INDEX(Data!$C:$C,80+$B33))} -> 1.6 | F33: {=IF($B33<=10, INDEX(Data!$D:$D,40+$B33), INDEX(Data!$D:$D,80+$B33))} -> 0.2 | G33: {=IF(INDEX(Data!$E:$E,IF($B33<=10,40+$B33,80+$B33))="Iris-setosa",0,1)} -> 0 | H33: =IF(G33=P33, 1, 0) -> 1 | I33: =I32-$K$4*T32 -> 0.26360882 | J33: =J32-$K$4*U32 -> -0.46972543 | K33: =K32-$K$4*V32 -> -0.32073508 | L33: =L32-$K$4*W32 -> 0.59865701 | M33: =M32-$K$4*X32 -> 0.61075766 | N33: =I33+J33*C33+K33*D33+L33*E33+F33*M33 -> -2.2707814 | O33: =1/(1+EXP(-N33)) -> 0.093571914 | P33: =IF(O33>0.5,1,0) -> 0 | Q33: =O33-G33 -> 0.093571914 | R33: =Q33^2 -> 0.0087557031 | T33: =2*(O33-G33)*(1-O33)*O33 -> 0.01587283 | U33: =2*(O33-G33)*(1-O33)*O33*C33 -> 0.080951435 | V33: =2*(O33-G33)*(1-O33)*O33*D33 -> 0.060316755 | W33: =2*(O33-G33)*(1-O33)*O33*E33 -> 0.025396529 | X33: =2*(O33-G33)*(1-O33)*O33*F33 -> 0.0031745661
B34: 8 | C34: {=IF($B34<=10, INDEX(Data!$A:$A,40+$B34), INDEX(Data!$A:$A,80+$B34))} -> 4.6 | D34: {=IF($B34<=10, INDEX(Data!$B:$B,40+$B34), INDEX(Data!$B:$B,80+$B34))} -> 3.2 | E34: {=IF($B34<=10, INDEX(Data!$C:$C,40+$B34), INDEX(Data!$C:$C,80+$B34))} -> 1.4 | F34: {=IF($B34<=10, INDEX(Data!$D:$D,40+$B34), INDEX(Data!$D:$D,80+$B34))} -> 0.2 | G34: {=IF(INDEX(Data!$E:$E,IF($B34<=10,40+$B34,80+$B34))="Iris-setosa",0,1)} -> 0 | H34: =IF(G34=P34, 1, 0) -> 1 | I34: =I33-$K$4*T33 -> 0.26202153 | J34: =J33-$K$4*U33 -> -0.47782057 | K34: =K33-$K$4*V33 -> -0.32676675 | L34: =L33-$K$4*W33 -> 0.59611736 | M34: =M33-$K$4*X33 -> 0.61044021 | N34: =I34+J34*C34+K34*D34+L34*E34+F34*M34 -> -2.0249544 | O34: =1/(1+EXP(-N34)) -> 0.11660767 | P34: =IF(O34>0.5,1,0) -> 0 | Q34: =O34-G34 -> 0.11660767 | R34: =Q34^2 -> 0.013597349 | T34: =2*(O34-G34)*(1-O34)*O34 -> 0.024023587 | U34: =2*(O34-G34)*(1-O34)*O34*C34 -> 0.1105085 | V34: =2*(O34-G34)*(1-O34)*O34*D34 -> 0.076875478 | W34: =2*(O34-G34)*(1-O34)*O34*E34 -> 0.033633021 | X34: =2*(O34-G34)*(1-O34)*O34*F34 -> 0.0048047174
B35: 9 | C35: {=IF($B35<=10, INDEX(Data!$A:$A,40+$B35), INDEX(Data!$A:$A,80+$B35))} -> 5.3 | D35: {=IF($B35<=10, INDEX(Data!$B:$B,40+$B35), INDEX(Data!$B:$B,80+$B35))} -> 3.7 | E35: {=IF($B35<=10, INDEX(Data!$C:$C,40+$B35), INDEX(Data!$C:$C,80+$B35))} -> 1.5 | F35: {=IF($B35<=10, INDEX(Data!$D:$D,40+$B35), INDEX(Data!$D:$D,80+$B35))} -> 0.2 | G35: {=IF(INDEX(Data!$E:$E,IF($B35<=10,40+$B35,80+$B35))="Iris-setosa",0,1)} -> 0 | H35: =IF(G35=P35, 1, 0) -> 1 | I35: =I34-$K$4*T34 -> 0.25961918 | J35: =J34-$K$4*U34 -> -0.48887142 | K35: =K34-$K$4*V34 -> -0.3344543 | L35: =L34-$K$4*W34 -> 0.59275405 | M35: =M34-$K$4*X34 -> 0.60995974 | N35: =I35+J35*C35+K35*D35+L35*E35+F35*M35 -> -2.5577573 | O35: =1/(1+EXP(-N35)) -> 0.071907072 | P35: =IF(O35>0.5,1,0) -> 0 | Q35: =O35-G35 -> 0.071907072 | R35: =Q35^2 -> 0.005170627 | T35: =2*(O35-G35)*(1-O35)*O35 -> 0.0095976446 | U35: =2*(O35-G35)*(1-O35)*O35*C35 -> 0.050867516 | V35: =2*(O35-G35)*(1-O35)*O35*D35 -> 0.035511285 | W35: =2*(O35-G35)*(1-O35)*O35*E35 -> 0.014396467 | X35: =2*(O35-G35)*(1-O35)*O35*F35 -> 0.0019195289
B36: 10 | C36: {=IF($B36<=10, INDEX(Data!$A:$A,40+$B36), INDEX(Data!$A:$A,80+$B36))} -> 5 | D36: {=IF($B36<=10, INDEX(Data!$B:$B,40+$B36), INDEX(Data!$B:$B,80+$B36))} -> 3.3 | E36: {=IF($B36<=10, INDEX(Data!$C:$C,40+$B36), INDEX(Data!$C:$C,80+$B36))} -> 1.4 | F36: {=IF($B36<=10, INDEX(Data!$D:$D,40+$B36), INDEX(Data!$D:$D,80+$B36))} -> 0.2 | G36: {=IF(INDEX(Data!$E:$E,IF($B36<=10,40+$B36,80+$B36))="Iris-setosa",0,1)} -> 0 | H36: =IF(G36=P36, 1, 0) -> 1 | I36: =I35-$K$4*T35 -> 0.25865941 | J36: =J35-$K$4*U35 -> -0.49395817 | K36: =K35-$K$4*V35 -> -0.33800543 | L36: =L35-$K$4*W35 -> 0.59131441 | M36: =M35-$K$4*X35 -> 0.60976778 | N36: =I36+J36*C36+K36*D36+L36*E36+F36*M36 -> -2.3767557 | O36: =1/(1+EXP(-N36)) -> 0.084962454 | P36: =IF(O36>0.5,1,0) -> 0 | Q36: =O36-G36 -> 0.084962454 | R36: =Q36^2 -> 0.0072186186 | T36: =2*(O36-G36)*(1-O36)*O36 -> 0.013210614 | U36: =2*(O36-G36)*(1-O36)*O36*C36 -> 0.066053071 | V36: =2*(O36-G36)*(1-O36)*O36*D36 -> 0.043595027 | W36: =2*(O36-G36)*(1-O36)*O36*E36 -> 0.01849486 | X36: =2*(O36-G36)*(1-O36)*O36*F36 -> 0.0026421228
B37: 11 | C37: {=IF($B37<=10, INDEX(Data!$A:$A,40+$B37), INDEX(Data!$A:$A,80+$B37))} -> 5.5 | D37: {=IF($B37<=10, INDEX(Data!$B:$B,40+$B37), INDEX(Data!$B:$B,80+$B37))} -> 2.6 | E37: {=IF($B37<=10, INDEX(Data!$C:$C,40+$B37), INDEX(Data!$C:$C,80+$B37))} -> 4.4 | F37: {=IF($B37<=10, INDEX(Data!$D:$D,40+$B37), INDEX(Data!$D:$D,80+$B37))} -> 1.2 | G37: {=IF(INDEX(Data!$E:$E,IF($B37<=10,40+$B37,80+$B37))="Iris-setosa",0,1)} -> 1 | H37: =IF(G37=P37, 1, 0) -> 0 | I37: =I36-$K$4*T36 -> 0.25733835 | J37: =J36-$K$4*U36 -> -0.50056348 | K37: =K36-$K$4*V36 -> -0.34236493 | L37: =L36-$K$4*W36 -> 0.58946492 | M37: =M36-$K$4*X36 -> 0.60950357 | N37: =I37+J37*C37+K37*D37+L37*E37+F37*M37 -> -0.060859685 | O37: =1/(1+EXP(-N37)) -> 0.48478977 | P37: =IF(O37>0.5,1,0) -> 0 | Q37: =O37-G37 -> -0.51521023 | R37: =Q37^2 -> 0.26544158 | T37: =2*(O37-G37)*(1-O37)*O37 -> -0.25736672 | U37: =2*(O37-G37)*(1-O37)*O37*C37 -> -1.415517 | V37: =2*(O37-G37)*(1-O37)*O37*D37 -> -0.66915348 | W37: =2*(O37-G37)*(1-O37)*O37*E37 -> -1.1324136 | X37: =2*(O37-G37)*(1-O37)*O37*F37 -> -0.30884007
B38: 12 | C38: {=IF($B38<=10, INDEX(Data!$A:$A,40+$B38), INDEX(Data!$A:$A,80+$B38))} -> 6.1 | D38: {=IF($B38<=10, INDEX(Data!$B:$B,40+$B38), INDEX(Data!$B:$B,80+$B38))} -> 3 | E38: {=IF($B38<=10, INDEX(Data!$C:$C,40+$B38), INDEX(Data!$C:$C,80+$B38))} -> 4.6 | F38: {=IF($B38<=10, INDEX(Data!$D:$D,40+$B38), INDEX(Data!$D:$D,80+$B38))} -> 1.4 | G38: {=IF(INDEX(Data!$E:$E,IF($B38<=10,40+$B38,80+$B38))="Iris-setosa",0,1)} -> 1 | H38: =IF(G38=P38, 1, 0) -> 1 | I38: =I37-$K$4*T37 -> 0.28307502 | J38: =J37-$K$4*U37 -> -0.35901178 | K38: =K37-$K$4*V37 -> -0.27544958 | L38: =L37-$K$4*W37 -> 0.70270628 | M38: =M37-$K$4*X37 -> 0.64038758 | N38: =I38+J38*C38+K38*D38+L38*E38+F38*M38 -> 1.3957459 | O38: =1/(1+EXP(-N38)) -> 0.80150796 | P38: =IF(O38>0.5,1,0) -> 1 | Q38: =O38-G38 -> -0.19849204 | R38: =Q38^2 -> 0.039399091 | T38: =2*(O38-G38)*(1-O38)*O38 -> -0.06315737 | U38: =2*(O38-G38)*(1-O38)*O38*C38 -> -0.38525996 | V38: =2*(O38-G38)*(1-O38)*O38*D38 -> -0.18947211 | W38: =2*(O38-G38)*(1-O38)*O38*E38 -> -0.2905239 | X38: =2*(O38-G38)*(1-O38)*O38*F38 -> -0.088420318
B39: 13 | C39: {=IF($B39<=10, INDEX(Data!$A:$A,40+$B39), INDEX(Data!$A:$A,80+$B39))} -> 5.8 | D39: {=IF($B39<=10, INDEX(Data!$B:$B,40+$B39), INDEX(Data!$B:$B,80+$B39))} -> 2.6 | E39: {=IF($B39<=10, INDEX(Data!$C:$C,40+$B39), INDEX(Data!$C:$C,80+$B39))} -> 4 | F39: {=IF($B39<=10, INDEX(Data!$D:$D,40+$B39), INDEX(Data!$D:$D,80+$B39))} -> 1.2 | G39: {=IF(INDEX(Data!$E:$E,IF($B39<=10,40+$B39,80+$B39))="Iris-setosa",0,1)} -> 1 | H39: =IF(G39=P39, 1, 0) -> 1 | I39: =I38-$K$4*T38 -> 0.28939076 | J39: =J38-$K$4*U38 -> -0.32048579 | K39: =K38-$K$4*V38 -> -0.25650237 | L39: =L38-$K$4*W38 -> 0.73175867 | M39: =M38-$K$4*X38 -> 0.64922961 | N39: =I39+J39*C39+K39*D39+L39*E39+F39*M39 -> 1.4697772 | O39: =1/(1+EXP(-N39)) -> 0.81302352 | P39: =IF(O39>0.5,1,0) -> 1 | Q39: =O39-G39 -> -0.18697648 | R39: =Q39^2 -> 0.034960203 | T39: =2*(O39-G39)*(1-O39)*O39 -> -0.056846934 | U39: =2*(O39-G39)*(1-O39)*O39*C39 -> -0.32971222 | V39: =2*(O39-G39)*(1-O39)*O39*D39 -> -0.14780203 | W39: =2*(O39-G39)*(1-O39)*O39*E39 -> -0.22738774 | X39: =2*(O39-G39)*(1-O39)*O39*F39 -> -0.068216321
... B45: 19 | C45: {=IF($B45<=10, INDEX(Data!$A:$A,40+$B45), INDEX(Data!$A:$A,80+$B45))} -> 5.1 | D45: {=IF($B45<=10, INDEX(Data!$B:$B,40+$B45), INDEX(Data!$B:$B,80+$B45))} -> 2.5 | E45: {=IF($B45<=10, INDEX(Data!$C:$C,40+$B45), INDEX(Data!$C:$C,80+$B45))} -> 3 | F45: {=IF($B45<=10, INDEX(Data!$D:$D,40+$B45), INDEX(Data!$D:$D,80+$B45))} -> 1.1 | G45: {=IF(INDEX(Data!$E:$E,IF($B45<=10,40+$B45,80+$B45))="Iris-setosa",0,1)} -> 1 | H45: =IF(G45=P45, 1, 0) -> 1 | I45: =I44-$K$4*T44 -> 0.30613825 | J45: =J44-$K$4*U44 -> -0.22816296 | K45: =K44-$K$4*V44 -> -0.21328063 | L45: =L44-$K$4*W44 -> 0.7957866 | M45: =M44-$K$4*X44 -> 0.66851374 | N45: =I45+J45*C45+K45*D45+L45*E45+F45*M45 -> 1.7320305 | O45: =1/(1+EXP(-N45)) -> 0.84967196 | P45: =IF(O45>0.5,1,0) -> 1 | Q45: =O45-G45 -> -0.15032804 | R45: =Q45^2 -> 0.02259852 | T45: =2*(O45-G45)*(1-O45)*O45 -> -0.038402658 | U45: =2*(O45-G45)*(1-O45)*O45*C45 -> -0.19585355 | V45: =2*(O45-G45)*(1-O45)*O45*D45 -> -0.096006644 | W45: =2*(O45-G45)*(1-O45)*O45*E45 -> -0.11520797 | X45: =2*(O45-G45)*(1-O45)*O45*F45 -> -0.042242923
B46: 20 | C46: {=IF($B46<=10, INDEX(Data!$A:$A,40+$B46), INDEX(Data!$A:$A,80+$B46))} -> 5.7 | D46: {=IF($B46<=10, INDEX(Data!$B:$B,40+$B46), INDEX(Data!$B:$B,80+$B46))} -> 2.8 | E46: {=IF($B46<=10, INDEX(Data!$C:$C,40+$B46), INDEX(Data!$C:$C,80+$B46))} -> 4.1 | F46: {=IF($B46<=10, INDEX(Data!$D:$D,40+$B46), INDEX(Data!$D:$D,80+$B46))} -> 1.3 | G46: {=IF(INDEX(Data!$E:$E,IF($B46<=10,40+$B46,80+$B46))="Iris-setosa",0,1)} -> 1 | H46: =IF(G46=P46, 1, 0) -> 1 | I46: =I45-$K$4*T45 -> 0.30997852 | J46: =J45-$K$4*U45 -> -0.2085776 | K46: =K45-$K$4*V45 -> -0.20367997 | L46: =L45-$K$4*W45 -> 0.8073074 | M46: =M45-$K$4*X45 -> 0.67273803 | N46: =I46+J46*C46+K46*D46+L46*E46+F46*M46 -> 2.735302 | O46: =1/(1+EXP(-N46)) -> 0.93907788 | P46: =IF(O46>0.5,1,0) -> 1 | Q46: =O46-G46 -> -0.060922123 | R46: =Q46^2 -> 0.0037115051 | S46: =AVERAGE(R27:R46) -> 0.064850082 | T46: =2*(O46-G46)*(1-O46)*O46 -> -0.0069707846 | U46: =2*(O46-G46)*(1-O46)*O46*C46 -> -0.039733472 | V46: =2*(O46-G46)*(1-O46)*O46*D46 -> -0.019518197 | W46: =2*(O46-G46)*(1-O46)*O46*E46 -> -0.028580217 | X46: =2*(O46-G46)*(1-O46)*O46*F46 -> -0.0090620199
